{
 "cells": [
  {
   "cell_type": "code",
   "execution_count": 6,
   "metadata": {},
   "outputs": [],
   "source": [
    "# Please include your imports in this cell\n",
    "import numpy as np\n",
    "#import keras\n",
    "import tensorflow as tf\n",
    "from tensorflow import keras\n",
    "from keras.models import Sequential\n",
    "from keras.layers import Dense, Dropout, Flatten\n",
    "from keras.layers import Conv2D, MaxPooling2D\n",
    "from keras.layers import Activation\n",
    "from keras.layers import BatchNormalization\n",
    "from keras.layers import LeakyReLU\n",
    "from keras.regularizers import l2\n",
    "from tensorflow.keras.optimizers import SGD ##needs to be changed to keras\n",
    "\n",
    "from scikeras.wrappers import KerasClassifier\n",
    "\n",
    "import imblearn\n",
    "import sklearn\n",
    "from  sklearn import metrics\n",
    "from sklearn.svm import SVC\n",
    "from sklearn.metrics import accuracy_score\n",
    "from sklearn.metrics import classification_report\n",
    "from sklearn.metrics import confusion_matrix, ConfusionMatrixDisplay\n",
    "from sklearn.metrics import roc_auc_score\n",
    "from sklearn.metrics import make_scorer\n",
    "from sklearn.model_selection import validation_curve\n",
    "from sklearn.model_selection import KFold\n",
    "from sklearn.model_selection import cross_val_score\n",
    "from sklearn.model_selection import GridSearchCV\n",
    "from sklearn.pipeline import Pipeline\n",
    "from sklearn.model_selection import GridSearchCV\n",
    "from sklearn.model_selection import cross_val_score\n",
    "\n",
    "import matplotlib.pyplot as plt\n",
    "\n",
    "import warnings\n",
    "warnings.filterwarnings(\"ignore\")\n",
    "\n",
    "%matplotlib inline"
   ]
  },
  {
   "cell_type": "code",
   "execution_count": 22,
   "metadata": {},
   "outputs": [],
   "source": [
    "X_train = np.load('Assignment2Data/X_train.npy')\n",
    "y_train = np.load('Assignment2Data/y_train.npy')\n",
    "X_test = np.load('Assignment2Data/X_test.npy')\n",
    "y_test = np.load('Assignment2Data/y_test.npy')"
   ]
  },
  {
   "cell_type": "code",
   "execution_count": 23,
   "metadata": {},
   "outputs": [],
   "source": [
    "X_train_n =  X_train/255.0\n",
    "X_test_n = X_test/255.0\n",
    "\n",
    "num_classes = 8\n",
    "y_train_c = keras.utils.to_categorical(y_train, num_classes)\n",
    "y_test_c = keras.utils.to_categorical(y_test, num_classes)"
   ]
  },
  {
   "cell_type": "code",
   "execution_count": 24,
   "metadata": {},
   "outputs": [
    {
     "data": {
      "image/png": "iVBORw0KGgoAAAANSUhEUgAAA1sAAAHUCAYAAADMRTIhAAAAOXRFWHRTb2Z0d2FyZQBNYXRwbG90bGliIHZlcnNpb24zLjcuMiwgaHR0cHM6Ly9tYXRwbG90bGliLm9yZy8pXeV/AAAACXBIWXMAAA9hAAAPYQGoP6dpAABI90lEQVR4nO3deXQUZfr+/6shKyE0JCGbQAir7CggBBf2PSDKDDqMERgEHNYIjAOiQ+SjoKjAfGUTF6IswuiAijiRIIs67GCGRURGiYISghgSYCBheX5/eKgfTRIIoYvukPfrnD6Hrnqq+q5K27dXVXW1wxhjBAAAAABwqzKeLgAAAAAAbkWELQAAAACwAWELAAAAAGxA2AIAAAAAGxC2AAAAAMAGhC0AAAAAsAFhCwAAAABsQNgCAAAAABsQtgAAAADABoStUmrXrl0aNGiQatasqcDAQAUGBqp27doaOnSotm/f7unybllff/21kpKSlJ6e7rZ1DhgwQNWrV3fb+txpypQp+uCDD2xZd3p6uhwOh5KTk21Z/41KSkqSw+HQL7/8clNfd86cOV67T4DrQZ/yDPqU+9mxT4tq/fr1cjgcev/992/q637yySdKSkq6qa/prQhbpdBrr72mZs2aacuWLRo9erQ+/vhjrVq1SomJidq7d69atGih7777ztNl3pK+/vprPfvss279wH3mmWe0YsUKt63PnexsYlFRUdq0aZN69Ohhy/pLKsIWbgX0Kc+hT7mfHfvU233yySd69tlnPV2GV/DxdAG4uf79739r2LBh6tGjh95//335+flZ89q3b6/hw4frvffeU2Bg4FXX87///U/lypWzu1wUQc2aNT1dglucOXNGAQEBcjgcRRrv7++vVq1a2VwVgJuNPnXruVX6FFAsBqVK9+7dja+vr/n555+LvEz//v1NUFCQ2bVrl+nUqZMpX768adWqlTHGmOPHj5s///nPJjo62vj6+prY2Fjz1FNPmbNnz1rLHzx40EgyCxYsyLduSWbSpEnW80mTJhlJZufOneaBBx4wwcHBpkKFCuaPf/yjyczMLFK9mzdvNvHx8SYkJMT4+/ubGjVqmNGjR7uM+eKLL0z79u1N+fLlTWBgoImLizMff/yxy5hLtVxpwYIFRpI5ePCgNS0mJsb06NHD/Otf/zJ33HGHCQgIMHXr1jVvvvlmvuWufFzaLzt37jQ9evQwlStXNn5+fiYqKsp0797dHDp06Krb279/fxMTE+MyTZIZPny4eeedd8ztt99uAgMDTePGjc3KlSuvuq6TJ08ap9NphgwZkm/ewYMHTZkyZcy0adOuuo7La7jy0aZNG5d98emnn5qBAweasLAwI8mcOXPGHDhwwAwYMMDUqlXLBAYGmujoaBMfH2927dqVr54r31eX/mZ79uwxDz/8sKlQoYIJDw83AwcONCdOnLhmzdf6G9j1Xv7ss89MmzZtTEhIiAkICDBVq1Y1Dz74oDl9+rQ1Jjc31/zf//2fqVu3rvHz8zNhYWFmwIABLuuKiYnJt8+vfG8A3o4+9Rv6VMFuVp8yxpgjR46YIUOGmNtuu834+vqa6tWrm6SkJHPu3DmX9cyZM8c0btzYBAUFmfLly5u6deuaCRMmGGOuvU8LkpmZaQYPHmyqVKlifd63bt3apKamWmNiYmJM//798y3bpk0bl21Yt26dkWQWLlxonnjiCRMREWECAgLMfffdZ3bu3Omy7HfffWceeughExUVZfz8/Ex4eLhp3769+eqrr1zGLV261LRq1cqUK1fOBAUFmc6dO7usq3///gVu8+Xvx9KEM1ulyIULF7Ru3To1b95cUVFR17VsXl6eevXqpaFDh2r8+PE6f/68zp49q3bt2um7777Ts88+q8aNG+uLL77Q1KlTlZaWplWrVhW71gceeEB9+/bV448/rr179+qZZ57R119/rS1btsjX17fQ5T799FP17NlT9erV0/Tp01WtWjWlp6dr9erV1pgNGzaoU6dOaty4sd588035+/trzpw56tmzp95991099NBDxar5P//5j8aOHavx48crIiJCb7zxhgYNGqRatWrpvvvuU48ePTRlyhQ99dRTmj17tu68805Jvx3xO336tDp16qTY2FjNnj1bERERysjI0Lp163Ty5Mli1bNq1Spt27ZNkydPVvny5TVt2jQ98MAD2r9/v2rUqFHgMuXLl9ef/vQnzZ8/X9OmTZPT6bTmzZkzR35+fvrTn/5UpNfftGmT2rdvr3bt2umZZ56RJFWoUMFlzJ/+9Cf16NFDCxcu1OnTp+Xr66uff/5ZoaGheuGFF1S5cmX9+uuvevvtt9WyZUt99dVXqlu37jVfu0+fPnrooYc0aNAg7d69WxMmTJAkvfXWW4UuY8ffQLr2ezk9PV09evTQvffeq7feeksVK1bUTz/9pJSUFOXl5alcuXK6ePGi7r//fn3xxRd68skn1bp1a/3www+aNGmS2rZtq+3btyswMFArVqzQ7373OzmdTs2ZM0fSb2cAgZKCPvUb+pTn+1RGRobuuusulSlTRn/7299Us2ZNbdq0Sc8995zS09O1YMECSdLSpUs1bNgwjRw5Ui+//LLKlCmj//73v/r6668l6ar7tDAJCQnauXOnnn/+edWpU0cnTpzQzp07dfz48SJtV0Geeuop3XnnnXrjjTeUnZ2tpKQktW3bVl999ZW1r7t3764LFy5o2rRpqlatmn755Rdt3LhRJ06csNYzZcoUPf300xo4cKCefvpp5eXl6aWXXtK9996rrVu3qn79+nrmmWd0+vRpvf/++9q0aZO17PX+N33L8HTaw82TkZFhJJmHH34437zz58+bc+fOWY+LFy9a8y4doXjrrbdclpk3b56RZP7xj3+4TH/xxReNJLN69WpjTPGOGD7xxBMu4xYvXmwkmUWLFl11G2vWrGlq1qxpzpw5U+iYVq1amfDwcHPy5EmX7W/YsKGpUqWKte3Xe8QwICDA/PDDD9a0M2fOmJCQEDN06FBr2nvvvWckmXXr1rmsc/v27UaS+eCDD666fQUp7IhhRESEycnJsaZlZGSYMmXKmKlTp151fd99950pU6aMmTFjhsu2hIaGmoEDB15XbUFBQQUeebu0Dx999NFrruP8+fMmLy/P1K5d2+V9cbUzW1ce1Rw2bJgJCAhweV9fqSh/Azvey++//76RZNLS0gp93XfffddIMv/85z9dpm/bts1IMnPmzLGmNWjQwOWoJlCS0Kd+Q5/yfJ8aOnSoKV++vMv+MsaYl19+2Ugye/fuNcYYM2LECFOxYsWrvkZh+7Qw5cuXN4mJiVcdc71ntu68806X/2bS09ONr6+veeyxx4wxxvzyyy9Gkpk5c2ahr/njjz8aHx8fM3LkSJfpJ0+eNJGRkaZv377WtOHDhxf43iyNuEEGJEnNmjWTr6+v9XjllVfyjenTp4/L87Vr1yooKEi/+93vXKYPGDBAkvTZZ58Vu54//vGPLs/79u0rHx8frVu3rtBlvv32W3333XcaNGiQAgICChxz+vRpbdmyRb/73e9Uvnx5a3rZsmWVkJCgw4cPa//+/cWquWnTpqpWrZr1PCAgQHXq1NEPP/xwzWVr1aqlSpUq6a9//avmzZtnHRG7Ee3atVNwcLD1PCIiQuHh4desp0aNGoqPj9ecOXNkjJEkLVmyRMePH9eIESNuuK7LXfmekqTz589rypQpql+/vvz8/OTj4yM/Pz8dOHBA+/btK9J6e/Xq5fK8cePGOnv2rDIzMwtdxo6/gXTt93LTpk3l5+enIUOG6O2339b333+fbx0ff/yxKlasqJ49e+r8+fPWo2nTpoqMjNT69evdUivgzehT9KlLbkaf+vjjj9WuXTtFR0e7fO5269ZN0m9nHyXprrvu0okTJ/SHP/xBH374oVvuQHvXXXcpOTlZzz33nDZv3qxz587d8Dr79evn8p3omJgYtW7d2nq/hoSEqGbNmnrppZc0ffp0ffXVV7p48aLLOj799FOdP39ejz76qMs+CQgIUJs2behFhSBslSJhYWEKDAws8ENsyZIl2rZtmz766KMCly1Xrly+S8COHz+uyMjIfDc0CA8Pl4+Pzw2d7o6MjHR57uPjo9DQ0Kuu89ixY5KkKlWqFDomKytLxpgCT2VHR0dLUrHrDg0NzTfN399fZ86cueayTqdTGzZsUNOmTfXUU0+pQYMGio6O1qRJk4r9IXsj9YwePVoHDhxQamqqJGn27NmKi4uzLn9wl4L+DmPGjNEzzzyj3r17a+XKldqyZYu2bdumJk2aFKl2Kf+2X7qU7mrL2/E3kK79Xq5Zs6bWrFmj8PBwDR8+XDVr1lTNmjX197//3Vrm6NGjOnHihPz8/Fz+Z9PX11cZGRk3/fbygF3oU/Qpb+lTR48e1cqVK/N95jZo0ECSrM/dhIQEvfXWW/rhhx/Up08fhYeHq2XLllZdxbFs2TL1799fb7zxhuLi4hQSEqJHH31UGRkZxV7nle/XS9MuvZccDoc+++wzdenSRdOmTdOdd96pypUra9SoUdZlokePHpUktWjRIt9+WbZsGb2oEHxnqxQpW7as2rdvr9WrV+vIkSMuH+T169eXpEJvS1rQHeJCQ0O1ZcsWGWNc5mdmZur8+fMKCwuTJOvoXW5ursvyV2sWGRkZuu2226zn58+f1/Hjxwv8YL6kcuXKkqTDhw8XOqZSpUoqU6aMjhw5km/ezz//LEkF1n35917s+jBp1KiRli5dKmOMdu3apeTkZE2ePFmBgYEaP368La9ZmPbt26thw4aaNWuWypcvr507d2rRokVuf52C3leLFi3So48+qilTprhM/+WXX1SxYkW313C5a/0N7Hov33vvvbr33nt14cIFbd++Xa+++qoSExMVERGhhx9+WGFhYQoNDVVKSkqBr3H5kWGgJKNP0aeKyu4+FRYWpsaNG+v5558vcP6l4CtJAwcO1MCBA3X69Gl9/vnnmjRpkuLj4/Xtt98qJiamWK89c+ZMzZw5Uz/++KM++ugjjR8/XpmZmVYfCAgIyPd+lX772196f1yuoKCWkZHh8n6NiYnRm2++Kem3s7D/+Mc/lJSUpLy8PM2bN89a7/vvv1+s7SqtOLNVykyYMEEXLlzQ448/fsOnpTt06KBTp07l+32Kd955x5ov/XZZQEBAgHbt2uUy7sMPPyx03YsXL3Z5/o9//EPnz59X27ZtC12mTp06qlmzpt56660CP4AkKSgoSC1bttTy5ctdjpxdvHhRixYtUpUqVVSnTh1Jsn6A8cq6V65cWWgN11KUMywOh0NNmjTRjBkzVLFiRe3cubPYr3cjRo0apVWrVmnChAmKiIjQ73//++teR1GPUF7O4XDku6nDqlWr9NNPP1336xdXYX8Du9/LZcuWVcuWLTV79mxJsl43Pj5ex48f14ULF9S8efN8j8tvGlKcfQ54E/oUfaqo7OxT8fHx2rNnj2rWrFng5+7lYeuSoKAgdevWTRMnTlReXp727t1rvYZ09X1amGrVqmnEiBHq1KmTy36uXr16vr/7t99+W+glpu+++651yaUk/fDDD9q4cWOh79c6dero6aefVqNGjazX7dKli3x8fPTdd98VuE+aN29uLX8j23yr4cxWKXP33Xdr9uzZGjlypO68804NGTJEDRo0sI6i/fOf/5SU/65xBXn00Uc1e/Zs9e/fX+np6WrUqJG+/PJLTZkyRd27d1fHjh0l/fah/Mgjj+itt95SzZo11aRJE23dulVLliwpdN3Lly+Xj4+POnXqZN3lqUmTJurbt+9Va5o9e7Z69uypVq1a6YknnlC1atX0448/6tNPP7Ua49SpU9WpUye1a9dO48aNk5+fn+bMmaM9e/bo3XfftY5+du/eXSEhIRo0aJAmT54sHx8fJScn69ChQ0Xa1wVp2LChJGn+/PkKDg5WQECAYmNjtWnTJs2ZM0e9e/dWjRo1ZIzR8uXLdeLECXXq1KnYr3cjHnnkEU2YMEGff/65nn76aZffuimqRo0aaf369Vq5cqWioqIUHBx8zbsJxsfHKzk5WbfffrsaN26sHTt26KWXXrrqZTfu8PHHH1/zb2DHe3nevHlau3atevTooWrVquns2bPWXRMv/Tf08MMPa/HixerevbtGjx6tu+66S76+vjp8+LDWrVun+++/Xw888ICk///I87Jly1SjRg0FBASoUaNGdu46wK3oU/SporKzT02ePFmpqalq3bq1Ro0apbp16+rs2bNKT0/XJ598onnz5qlKlSoaPHiwAgMDdffddysqKkoZGRmaOnWqnE6nWrRoIanwfVrQWdDs7Gy1a9dO/fr10+23367g4GBt27ZNKSkpevDBB61xCQkJeuSRRzRs2DD16dNHP/zwg6ZNm2adPb1SZmamHnjgAQ0ePFjZ2dmaNGmSAgICrLv17tq1SyNGjNDvf/971a5dW35+flq7dq127dplnbWsXr26Jk+erIkTJ+r7779X165dValSJR09elRbt25VUFCQ9UPGl/rOiy++qG7duqls2bJq3Lhxsf5GJZ5HbssBj0tLSzMDBw40sbGxxt/f3wQEBJhatWqZRx991Hz22WcuYy/9fklBjh8/bh5//HETFRVlfHx8TExMjJkwYYLL75cYY0x2drZ57LHHTEREhAkKCjI9e/Y06enphd7laceOHaZnz56mfPnyJjg42PzhD38wR48eLdK2bdq0yXTr1s04nU7j7+9vatasme+uUZd+vyQoKMgEBgaaVq1aFfjbHlu3bjWtW7c2QUFB5rbbbjOTJk0yb7zxRqG/X3KlK+8KZIwxM2fONLGxsaZs2bLW3a+++eYb84c//MHUrFnTBAYGGqfTae666y6TnJx8ze292u+XXKmwuxcVZsCAAcbHx8ccPny4yMtcLi0tzdx9992mXLlyBf7O1rZt2/Itk5WVZQYNGmTCw8NNuXLlzD333GO++OKLfPvyancjPHbsmMs6C7oz15WK+jdw93t506ZN5oEHHjAxMTHG39/fhIaGmjZt2piPPvrI5XXPnTtnXn75ZdOkSRMTEBBgypcvb26//XYzdOhQc+DAAWtcenq66dy5swkODuZ3tlCi0afoU0VhV58yxphjx46ZUaNGmdjYWOPr62tCQkJMs2bNzMSJE82pU6eMMca8/fbbpl27diYiIsL4+fmZ6Oho07dv33y/DVnQPi3I2bNnzeOPP24aN25sKlSoYAIDA03dunXNpEmTXH578eLFi2batGmmRo0aJiAgwDRv3tysXbv2qr+zNWrUKFO5cmXj7+9v7r33XrN9+3Zr3NGjR82AAQPM7bffbv1eWOPGjc2MGTPM+fPnXWr84IMPTLt27UyFChWMv7+/iYmJMb/73e/MmjVrrDG5ubnmscceM5UrVzYOh6NU/86Ww5jLzikCHpaUlKRnn31Wx44dK/CaY9w8eXl5ql69uu655x794x//8HQ5AOAV6FPegz6FkoDLCAG4OHbsmPbv368FCxbo6NGjN/1LzwAAXA19CiUJYQuAi1WrVmngwIGKiorSnDlzCryN7vnz56+6jjJlyqhMGe6/AwBwP/oUShIuIwRw3Qq6xfLl+vfvr+Tk5JtTDAAAV6BPwVt4NNLPnTtXjRs3VoUKFVShQgXFxcXpX//6lzXfGKOkpCRFR0crMDBQbdu2tW6jeUlubq5GjhypsLAwBQUFqVevXvl+vyIrK0sJCQlyOp1yOp1KSEjQiRMnbsYmArekbdu2XfWRlJTk6RKBYqEvAbcG+hS8hUfPbK1cuVJly5ZVrVq1JElvv/22XnrpJX311Vdq0KCBXnzxRT3//PNKTk5WnTp19Nxzz+nzzz/X/v37rR/x/POf/6yVK1cqOTlZoaGhGjt2rH799Vft2LFDZcuWlSR169ZNhw8f1vz58yVJQ4YMUfXq1W/odygAALce+hIAwK08dyPEglWqVMm88cYb5uLFiyYyMtK88MIL1ryzZ88ap9Np5s2bZ4wx5sSJE8bX19csXbrUGvPTTz+ZMmXKmJSUFGOMMV9//bWRZDZv3myN2bRpk5Fkvvnmm5u0VQCAkoq+BAAoLq+5QcaFCxf03nvv6fTp04qLi9PBgweVkZGhzp07W2P8/f3Vpk0bbdy4UUOHDtWOHTt07tw5lzHR0dFq2LChNm7cqC5dumjTpk1yOp1q2bKlNaZVq1ZyOp3auHFjoT+wmpub6/Lr7hcvXtSvv/6q0NDQa14HDABwH2OMTp48qejo6Jv6hXZv60sSvQkAvEVRe5PHw9bu3bsVFxens2fPqnz58lqxYoXq16+vjRs3SpIiIiJcxkdEROiHH36QJGVkZMjPz0+VKlXKNyYjI8MaEx4enu91w8PDrTEFmTp1qvUr2AAAzzt06JCqVKli++t4a1+S6E0A4G2u1Zs8Hrbq1q2rtLQ0nThxQv/85z/Vv39/bdiwwZp/5ZE6Y8w1j95dOaag8ddaz4QJEzRmzBjreXZ2tqpVq6ZDhw6pQoUK19wuAIB75OTkqGrVqtZ3ouzmrX1JojcBgLcoam/yeNjy8/OzvojcvHlzbdu2TX//+9/117/+VdJvRwCjoqKs8ZmZmdZRxcjISOXl5SkrK8vlKGJmZqZat25tjTl69Gi+1z127Fi+o5OX8/f3l7+/f77pl+5QBQC4uW7WZXLe2pckehMAeJtr9Sav+zU3Y4xyc3MVGxuryMhIpaamWvPy8vK0YcMGq2E1a9ZMvr6+LmOOHDmiPXv2WGPi4uKUnZ2trVu3WmO2bNmi7OxsawwAAIWhLwEAisujZ7aeeuopdevWTVWrVtXJkye1dOlSrV+/XikpKXI4HEpMTNSUKVNUu3Zt1a5dW1OmTFG5cuXUr18/SZLT6dSgQYM0duxYhYaGKiQkROPGjVOjRo3UsWNHSVK9evXUtWtXDR48WK+99pqk326xGx8ff9UvIQMASh/6EgDAnTwato4ePaqEhAQdOXJETqdTjRs3VkpKijp16iRJevLJJ3XmzBkNGzZMWVlZatmypVavXu1ybeSMGTPk4+Ojvn376syZM+rQoYOSk5Ot3zKRpMWLF2vUqFHW3aF69eqlWbNm3dyNBQB4PfoSAMCdPPqjxiVJTk6OnE6nsrOzuS4eAG4iPn8Lx74BAM8o6uev131nCwAAAABuBYQtAAAAALABYQsAAAAAbEDYAgAAAAAbELYAAAAAwAaELQAAAACwAWELAAAAAGxA2AIAAAAAGxC2AAAAAMAGhC0AAAAAsAFhCwAAAABsQNgCAAAAABsQtgAAAADABoQtAAAAALABYQsAAAAAbEDYAgAAAAAbELYAAAAAwAaELQAAAACwAWELAAAAAGxA2AIAAAAAGxC2AAAAAMAGhC0AAAAAsAFhCwAAAABsQNgCAAAAABsQtgAAAADABoQtAAAAALABYQsAAAAAbEDYAgAAAAAbELYAAAAAwAaELQAAAACwAWELAAAAAGxA2AIAAAAAGxC2AAAAAMAGhC0AAAAAsAFhCwAAAABsQNgCAAAAABv4eLoAACjJqo9f5ekSlP5CD0+XAAAACsCZLQAAAACwAWELAAAAAGxA2AIAAAAAGxC2AAAAAMAGhC0AAAAAsAFhCwAAAABsQNgCAAAAABsQtgAAAADABoQtAAAAALABYQsAAAAAbEDYAgAAAAAbELYAAAAAwAaELQAAAACwAWELAAAAAGxA2AIAAAAAGxC2AAAAAMAGHg1bU6dOVYsWLRQcHKzw8HD17t1b+/fvdxkzYMAAORwOl0erVq1cxuTm5mrkyJEKCwtTUFCQevXqpcOHD7uMycrKUkJCgpxOp5xOpxISEnTixAm7NxEAUILQlwAA7uTRsLVhwwYNHz5cmzdvVmpqqs6fP6/OnTvr9OnTLuO6du2qI0eOWI9PPvnEZX5iYqJWrFihpUuX6ssvv9SpU6cUHx+vCxcuWGP69euntLQ0paSkKCUlRWlpaUpISLgp2wkAKBnoSwAAd/Lx5IunpKS4PF+wYIHCw8O1Y8cO3XfffdZ0f39/RUZGFriO7Oxsvfnmm1q4cKE6duwoSVq0aJGqVq2qNWvWqEuXLtq3b59SUlK0efNmtWzZUpL0+uuvKy4uTvv371fdunVt2kIAQElCXwIAuJNXfWcrOztbkhQSEuIyff369QoPD1edOnU0ePBgZWZmWvN27Nihc+fOqXPnzta06OhoNWzYUBs3bpQkbdq0SU6n02poktSqVSs5nU5rzJVyc3OVk5Pj8gAAlC7e1JckehMAlDReE7aMMRozZozuueceNWzY0JrerVs3LV68WGvXrtUrr7yibdu2qX379srNzZUkZWRkyM/PT5UqVXJZX0REhDIyMqwx4eHh+V4zPDzcGnOlqVOnWtfRO51OVa1a1V2bCgAoAbytL0n0JgAoaTx6GeHlRowYoV27dunLL790mf7QQw9Z/27YsKGaN2+umJgYrVq1Sg8++GCh6zPGyOFwWM8v/3dhYy43YcIEjRkzxnqek5NTKppa9fGrPF2C0l/o4ekSAMDr+pJUensTAJRUXnFma+TIkfroo4+0bt06ValS5apjo6KiFBMTowMHDkiSIiMjlZeXp6ysLJdxmZmZioiIsMYcPXo037qOHTtmjbmSv7+/KlSo4PIAAJQO3tiXJHoTAJQ0Hg1bxhiNGDFCy5cv19q1axUbG3vNZY4fP65Dhw4pKipKktSsWTP5+voqNTXVGnPkyBHt2bNHrVu3liTFxcUpOztbW7dutcZs2bJF2dnZ1hgAAOhLAAB38uhlhMOHD9eSJUv04YcfKjg42LpO3el0KjAwUKdOnVJSUpL69OmjqKgopaen66mnnlJYWJgeeOABa+ygQYM0duxYhYaGKiQkROPGjVOjRo2su0DVq1dPXbt21eDBg/Xaa69JkoYMGaL4+Hju+AQAsNCXAADu5NGwNXfuXElS27ZtXaYvWLBAAwYMUNmyZbV792698847OnHihKKiotSuXTstW7ZMwcHB1vgZM2bIx8dHffv21ZkzZ9ShQwclJyerbNmy1pjFixdr1KhR1t2hevXqpVmzZtm/kQCAEoO+BABwJ4cxxni6iJIgJydHTqdT2dnZt/Q18twgA7g+/Ddjv9Ly+Vsc7BsA8Iyifv56xQ0yAAAAAOBWQ9gCAAAAABsQtgAAAADABoQtAAAAALABYQsAAAAAbEDYAgAAAAAbELYAAAAAwAaELQAAAACwAWELAAAAAGxA2AIAAAAAGxC2AAAAAMAGhC0AAAAAsAFhCwAAAABsQNgCAAAAABsQtgAAAADABoQtAAAAALABYQsAAAAAbODj6QKAW1H18as8XYLSX+jh6RIAAABKNc5sAQAAAIANCFsAAAAAYAPCFgAAAADYgLAFAAAAADYgbAEAAACADQhbAAAAAGADwhYAAAAA2ICwBQAAAAA2IGwBAAAAgA0IWwAAAABgA8IWAAAAANiAsAUAAAAANiBsAQAAAIANCFsAAAAAYAPCFgAAAADYgLAFAAAAADYgbAEAAACADQhbAAAAAGADwhYAAAAA2ICwBQAAAAA2IGwBAAAAgA0IWwAAAABgA8IWAAAAANiAsAUAAAAANiBsAQAAAIANCFsAAAAAYAPCFgAAAADYgLAFAAAAADYgbAEAAACADQhbAAAAAGADwhYAAAAA2ICwBQAAAAA2IGwBAAAAgA0IWwAAAABgA8IWAAAAANjAo2Fr6tSpatGihYKDgxUeHq7evXtr//79LmOMMUpKSlJ0dLQCAwPVtm1b7d2712VMbm6uRo4cqbCwMAUFBalXr146fPiwy5isrCwlJCTI6XTK6XQqISFBJ06csHsTAQAlCH0JAOBOHg1bGzZs0PDhw7V582alpqbq/Pnz6ty5s06fPm2NmTZtmqZPn65Zs2Zp27ZtioyMVKdOnXTy5ElrTGJiolasWKGlS5fqyy+/1KlTpxQfH68LFy5YY/r166e0tDSlpKQoJSVFaWlpSkhIuKnbCwDwbvQlAIA7OYwxxtNFXHLs2DGFh4drw4YNuu+++2SMUXR0tBITE/XXv/5V0m9HCyMiIvTiiy9q6NChys7OVuXKlbVw4UI99NBDkqSff/5ZVatW1SeffKIuXbpo3759ql+/vjZv3qyWLVtKkjZv3qy4uDh98803qlu37jVry8nJkdPpVHZ2tipUqGDfTvCw6uNXeboEpb/Qw9Ml3DD2Y+nB39p+nvz89ea+JJWe3gQA3qaon79e9Z2t7OxsSVJISIgk6eDBg8rIyFDnzp2tMf7+/mrTpo02btwoSdqxY4fOnTvnMiY6OloNGza0xmzatElOp9NqaJLUqlUrOZ1Oa8yVcnNzlZOT4/IAAJQu3tSXJHoTAJQ0XhO2jDEaM2aM7rnnHjVs2FCSlJGRIUmKiIhwGRsREWHNy8jIkJ+fnypVqnTVMeHh4fleMzw83BpzpalTp1rX0TudTlWtWvXGNhAAUKJ4W1+S6E0AUNJ4TdgaMWKEdu3apXfffTffPIfD4fLcGJNv2pWuHFPQ+KutZ8KECcrOzrYehw4dKspmAABuEd7WlyR6EwCUNF4RtkaOHKmPPvpI69atU5UqVazpkZGRkpTvKF9mZqZ1VDEyMlJ5eXnKysq66pijR4/me91jx47lOzp5ib+/vypUqODyAACUDt7YlyR6EwCUNB4NW8YYjRgxQsuXL9fatWsVGxvrMj82NlaRkZFKTU21puXl5WnDhg1q3bq1JKlZs2by9fV1GXPkyBHt2bPHGhMXF6fs7Gxt3brVGrNlyxZlZ2dbYwAAoC8BANzJx5MvPnz4cC1ZskQffvihgoODrSOFTqdTgYGBcjgcSkxM1JQpU1S7dm3Vrl1bU6ZMUbly5dSvXz9r7KBBgzR27FiFhoYqJCRE48aNU6NGjdSxY0dJUr169dS1a1cNHjxYr732miRpyJAhio+PL/IdnwAAtz76EgDAnTwatubOnStJatu2rcv0BQsWaMCAAZKkJ598UmfOnNGwYcOUlZWlli1bavXq1QoODrbGz5gxQz4+Purbt6/OnDmjDh06KDk5WWXLlrXGLF68WKNGjbLuDtWrVy/NmjXL3g0EAJQo9CUAgDt51e9sebPS8lsm/GaQe7AfSw/+1vYrLZ+/xcG+AQDPKJG/swUAAAAAtwrCFgAAAADYgLAFAAAAADYgbAEAAACADQhbAAAAAGADwhYAAAAA2ICwBQAAAAA2IGwBAAAAgA0IWwAAAABgAx9PFwAAsFf18as8XYLSX+jh6RIAALjpOLMFAAAAADYgbAEAAACADQhbAAAAAGADwhYAAAAA2ICwBQAAAAA2IGwBAAAAgA0IWwAAAABgA8IWAAAAANiAsAUAAAAANiBsAQAAAIANCFsAAAAAYAPCFgAAAADYgLAFAAAAADYgbAEAAACADQhbAAAAAGADwhYAAAAA2ICwBQAAAAA2IGwBAAAAgA0IWwAAAABgA8IWAAAAANiAsAUAAAAANiBsAQAAAIANCFsAAAAAYAPCFgAAAADYgLAFAAAAADYgbAEAAACADYoVtnbu3Kndu3dbzz/88EP17t1bTz31lPLy8txWHAAARUFfAgB4o2KFraFDh+rbb7+VJH3//fd6+OGHVa5cOb333nt68skn3VogAADXQl8CAHijYoWtb7/9Vk2bNpUkvffee7rvvvu0ZMkSJScn65///Kc76wMA4JroSwAAb1SssGWM0cWLFyVJa9asUffu3SVJVatW1S+//OK+6gAAKAL6EgDAGxUrbDVv3lzPPfecFi5cqA0bNqhHjx6SpIMHDyoiIsKtBQIAcC30JQCANypW2JoxY4Z27typESNGaOLEiapVq5Yk6f3331fr1q3dWiAAANdCXwIAeCOf4izUpEkTl7s+XfLSSy/Jx6dYqwQAoNjoSwAAb1SsM1s1atTQ8ePH800/e/as6tSpc8NFAQBwPehLAABvVKywlZ6ergsXLuSbnpubq8OHD99wUQAAXA/6EgDAG13XtRUfffSR9e9PP/1UTqfTen7hwgV99tlnio2NdV91AABcBX0JAODNrits9e7dW5LkcDjUv39/l3m+vr6qXr26XnnlFbcVBwDA1dCXAADe7LrC1qXfMImNjdW2bdsUFhZmS1EAABQFfQkA4M2KdYumgwcPursOAACKjb4EAPBGxb4f7meffabPPvtMmZmZ1pHFS956660bLgwAgOtBXwIAeJtiha1nn31WkydPVvPmzRUVFSWHw+HuugAAKDL6EgDAGxUrbM2bN0/JyclKSEhwdz0AAFw3+hIAwBsV63e28vLy1Lp1a3fXAgBAsdCXAADeqFhh67HHHtOSJUtu+MU///xz9ezZU9HR0XI4HPrggw9c5g8YMEAOh8Pl0apVK5cxubm5GjlypMLCwhQUFKRevXrl+wHLrKwsJSQkyOl0yul0KiEhQSdOnLjh+gEA3sFdfUmiNwEA3KdYlxGePXtW8+fP15o1a9S4cWP5+vq6zJ8+fXqR1nP69Gk1adJEAwcOVJ8+fQoc07VrVy1YsMB67ufn5zI/MTFRK1eu1NKlSxUaGqqxY8cqPj5eO3bsUNmyZSVJ/fr10+HDh5WSkiJJGjJkiBISErRy5coibzMAwHu5qy9J9CYAgPsUK2zt2rVLTZs2lSTt2bPHZd71fCm5W7du6tat21XH+Pv7KzIyssB52dnZevPNN7Vw4UJ17NhRkrRo0SJVrVpVa9asUZcuXbRv3z6lpKRo8+bNatmypSTp9ddfV1xcnPbv36+6desWuV4AgHdyV1+S6E0AAPcpVthat26du+so1Pr16xUeHq6KFSuqTZs2ev755xUeHi5J2rFjh86dO6fOnTtb46Ojo9WwYUNt3LhRXbp00aZNm+R0Oq1mJkmtWrWS0+nUxo0bC21oubm5ys3NtZ7n5OTYtIUAgBt1M/uSRG8CABRNsb6zdbN069ZNixcv1tq1a/XKK69o27Ztat++vdVoMjIy5Ofnp0qVKrksFxERoYyMDGvMpQZ4ufDwcGtMQaZOnWpdR+90OlW1alU3bhkAoKSiNwEAiqpYZ7batWt31csy1q5dW+yCLvfQQw9Z/27YsKGaN2+umJgYrVq1Sg8++GChyxljXOorqNYrx1xpwoQJGjNmjPU8JyeHpgYAXupm9SWJ3gQAKLpiha1L18Vfcu7cOaWlpWnPnj3q37+/O+oqUFRUlGJiYnTgwAFJUmRkpPLy8pSVleVyBDEzM9O6BXBkZKSOHj2ab13Hjh1TREREoa/l7+8vf39/N28BAMAOnupLEr0JAFC4YoWtGTNmFDg9KSlJp06duqGCrub48eM6dOiQoqKiJEnNmjWTr6+vUlNT1bdvX0nSkSNHtGfPHk2bNk2SFBcXp+zsbG3dulV33XWXJGnLli3Kzs7mN1kA4Bbhqb4k0ZsAAIUrVtgqzCOPPKK77rpLL7/8cpHGnzp1Sv/973+t5wcPHlRaWppCQkIUEhKipKQk9enTR1FRUUpPT9dTTz2lsLAwPfDAA5Ikp9OpQYMGaezYsQoNDVVISIjGjRunRo0aWXeAqlevnrp27arBgwfrtddek/Tb7XXj4+O52xMA3OKuty9J9CYAgPu4NWxt2rRJAQEBRR6/fft2tWvXznp+6Tr0/v37a+7cudq9e7feeecdnThxQlFRUWrXrp2WLVum4OBga5kZM2bIx8dHffv21ZkzZ9ShQwclJydbv2MiSYsXL9aoUaOsO0P16tVLs2bNutHNBQB4uevtSxK9CQDgPsUKW1d+AdgYoyNHjmj79u165plniryetm3byhhT6PxPP/30musICAjQq6++qldffbXQMSEhIVq0aFGR6wIAlCzu6ksSvQkA4D7FCltOp9PleZkyZVS3bl1NnjzZ5XdFAAC4GehLAABvVKywtWDBAnfXAQBAsdGXAADe6Ia+s7Vjxw7t27dPDodD9evX1x133OGuugAAuG70JQCANylW2MrMzNTDDz+s9evXq2LFijLGKDs7W+3atdPSpUtVuXJld9cJAECh6EsAAG9UpjgLjRw5Ujk5Odq7d69+/fVXZWVlac+ePcrJydGoUaPcXSMAAFdFXwIAeKNindlKSUnRmjVrVK9ePWta/fr1NXv2bL6IDAC46ehLAABvVKwzWxcvXpSvr2++6b6+vrp48eINFwUAwPWgLwEAvFGxwlb79u01evRo/fzzz9a0n376SU888YQ6dOjgtuIAACgK+hIAwBsVK2zNmjVLJ0+eVPXq1VWzZk3VqlVLsbGxOnny5FV/wBEAADvQlwAA3qhY39mqWrWqdu7cqdTUVH3zzTcyxqh+/frq2LGju+sDAOCa6EsAAG90XWe21q5dq/r16ysnJ0eS1KlTJ40cOVKjRo1SixYt1KBBA33xxRe2FAoAwJXoSwAAb3ZdYWvmzJkaPHiwKlSokG+e0+nU0KFDNX36dLcVBwDA1dCXAADe7LrC1n/+8x917dq10PmdO3fWjh07brgoAACKgr4EAPBm1xW2jh49WuCtdS/x8fHRsWPHbrgoAACKgr4EAPBm1xW2brvtNu3evbvQ+bt27VJUVNQNFwUAQFHQlwAA3uy6wlb37t31t7/9TWfPns0378yZM5o0aZLi4+PdVhwAAFdDXwIAeLPruvX7008/reXLl6tOnToaMWKE6tatK4fDoX379mn27Nm6cOGCJk6caFetAAC4oC8BALzZdYWtiIgIbdy4UX/+8581YcIEGWMkSQ6HQ126dNGcOXMUERFhS6EAAFyJvgQA8GbX/aPGMTEx+uSTT5SVlaX//ve/Msaodu3aqlSpkh31AQBwVfQlAIC3uu6wdUmlSpXUokULd9YCAECx0ZcAAN7mum6QAQAAAAAoGsIWAAAAANiAsAUAAAAANiBsAQAAAIANCFsAAAAAYAPCFgAAAADYoNi3fgc8pfr4VZ4uQekv9PB0CQAAAPBynNkCAAAAABsQtgAAAADABoQtAAAAALABYQsAAAAAbEDYAgAAAAAbELYAAAAAwAaELQAAAACwAWELAAAAAGxA2AIAAAAAGxC2AAAAAMAGhC0AAAAAsAFhCwAAAABsQNgCAAAAABv4eLoAAChM9fGrPF2C0l/o4ekSAABACcWZLQAAAACwAWELAAAAAGxA2AIAAAAAGxC2AAAAAMAGhC0AAAAAsAFhCwAAAABsQNgCAAAAABsQtgAAAADABoQtAAAAALABYQsAAAAAbEDYAgAAAAAbELYAAAAAwAYeDVuff/65evbsqejoaDkcDn3wwQcu840xSkpKUnR0tAIDA9W2bVvt3bvXZUxubq5GjhypsLAwBQUFqVevXjp8+LDLmKysLCUkJMjpdMrpdCohIUEnTpyweesAACURvQkA4C4eDVunT59WkyZNNGvWrALnT5s2TdOnT9esWbO0bds2RUZGqlOnTjp58qQ1JjExUStWrNDSpUv15Zdf6tSpU4qPj9eFCxesMf369VNaWppSUlKUkpKitLQ0JSQk2L59AICSh94EAHAXH0++eLdu3dStW7cC5xljNHPmTE2cOFEPPvigJOntt99WRESElixZoqFDhyo7O1tvvvmmFi5cqI4dO0qSFi1apKpVq2rNmjXq0qWL9u3bp5SUFG3evFktW7aUJL3++uuKi4vT/v37Vbdu3ZuzsQCAEoHeBABwF6/9ztbBgweVkZGhzp07W9P8/f3Vpk0bbdy4UZK0Y8cOnTt3zmVMdHS0GjZsaI3ZtGmTnE6n1cwkqVWrVnI6ndaYguTm5ionJ8flAQAo3ehNAIDr4bVhKyMjQ5IUERHhMj0iIsKal5GRIT8/P1WqVOmqY8LDw/OtPzw83BpTkKlTp1rX0TudTlWtWvWGtgcAUPLRmwAA18Nrw9YlDofD5bkxJt+0K105pqDx11rPhAkTlJ2dbT0OHTp0nZUDAG5V9CYAQFF4bdiKjIyUpHxH+DIzM60jipGRkcrLy1NWVtZVxxw9ejTf+o8dO5bvyOTl/P39VaFCBZcHAKB0ozcBAK6H14at2NhYRUZGKjU11ZqWl5enDRs2qHXr1pKkZs2aydfX12XMkSNHtGfPHmtMXFycsrOztXXrVmvMli1blJ2dbY0BAKAo6E0AgOvh0bsRnjp1Sv/973+t5wcPHlRaWppCQkJUrVo1JSYmasqUKapdu7Zq166tKVOmqFy5curXr58kyel0atCgQRo7dqxCQ0MVEhKicePGqVGjRtYdoOrVq6euXbtq8ODBeu211yRJQ4YMUXx8/E2/21P18atu6usVJP2FHp4uAV6C9yNQsNLWmwAA9vFo2Nq+fbvatWtnPR8zZowkqX///kpOTtaTTz6pM2fOaNiwYcrKylLLli21evVqBQcHW8vMmDFDPj4+6tu3r86cOaMOHTooOTlZZcuWtcYsXrxYo0aNsu4M1atXr0J/PwUAULrRmwAA7uLRsNW2bVsZYwqd73A4lJSUpKSkpELHBAQE6NVXX9Wrr75a6JiQkBAtWrToRkoFAJQS9CYAgLt47Xe2AAAAAKAkI2wBAAAAgA0IWwAAAABgA8IWAAAAANiAsAUAAAAANiBsAQAAAIANCFsAAAAAYAPCFgAAAADYgLAFAAAAADYgbAEAAACADQhbAAAAAGADwhYAAAAA2ICwBQAAAAA2IGwBAAAAgA0IWwAAAABgA8IWAAAAANiAsAUAAAAANiBsAQAAAIANCFsAAAAAYAPCFgAAAADYgLAFAAAAADYgbAEAAACADQhbAAAAAGADwhYAAAAA2ICwBQAAAAA2IGwBAAAAgA0IWwAAAABgA8IWAAAAANiAsAUAAAAANiBsAQAAAIANCFsAAAAAYAPCFgAAAADYgLAFAAAAADYgbAEAAACADQhbAAAAAGADwhYAAAAA2MDH0wUAAAAAcJ/q41d5ugSlv9DD0yV4Bc5sAQAAAIANCFsAAAAAYAPCFgAAAADYgLAFAAAAADYgbAEAAACADbgbIQAA8GqevrMad1UDUFyc2QIAAAAAGxC2AAAAAMAGhC0AAAAAsAFhCwAAAABswA0yAAAASgFP32hE4mYjKH04swUAAAAANiBsAQAAAIANCFsAAAAAYAPCFgAAAADYgLAFAAAAADYgbAEAAACADbw6bCUlJcnhcLg8IiMjrfnGGCUlJSk6OlqBgYFq27at9u7d67KO3NxcjRw5UmFhYQoKClKvXr10+PDhm70pAIBbBL0JAFBUXh22JKlBgwY6cuSI9di9e7c1b9q0aZo+fbpmzZqlbdu2KTIyUp06ddLJkyetMYmJiVqxYoWWLl2qL7/8UqdOnVJ8fLwuXLjgic0BANwC6E0AgKLw+h819vHxcTlieIkxRjNnztTEiRP14IMPSpLefvttRUREaMmSJRo6dKiys7P15ptvauHCherYsaMkadGiRapatarWrFmjLl263NRtAQDcGuhNAICi8PozWwcOHFB0dLRiY2P18MMP6/vvv5ckHTx4UBkZGercubM11t/fX23atNHGjRslSTt27NC5c+dcxkRHR6thw4bWmMLk5uYqJyfH5QEAgERvAgAUjVeHrZYtW+qdd97Rp59+qtdff10ZGRlq3bq1jh8/royMDElSRESEyzIRERHWvIyMDPn5+alSpUqFjinM1KlT5XQ6rUfVqlXduGUAgJKK3gQAKCqvDlvdunVTnz591KhRI3Xs2FGrVq2S9NslGZc4HA6XZYwx+aZdqShjJkyYoOzsbOtx6NChYm4FAOBWQm8CABSVV4etKwUFBalRo0Y6cOCAda38lUcBMzMzrSOKkZGRysvLU1ZWVqFjCuPv768KFSq4PAAAuBK9CQBQGK+/QcblcnNztW/fPt17772KjY1VZGSkUlNTdccdd0iS8vLytGHDBr344ouSpGbNmsnX11epqanq27evJOnIkSPas2ePpk2b5rHtAADcOuhNAHD9qo9f5ekSlP5CD9tfw6vD1rhx49SzZ09Vq1ZNmZmZeu6555STk6P+/fvL4XAoMTFRU6ZMUe3atVW7dm1NmTJF5cqVU79+/SRJTqdTgwYN0tixYxUaGqqQkBCNGzfOuvQDAIDrRW8CABSVV4etw4cP6w9/+IN++eUXVa5cWa1atdLmzZsVExMjSXryySd15swZDRs2TFlZWWrZsqVWr16t4OBgax0zZsyQj4+P+vbtqzNnzqhDhw5KTk5W2bJlPbVZAIASjN4EACgqrw5bS5cuvep8h8OhpKQkJSUlFTomICBAr776ql599VU3VwcAKI3oTQCAoipRN8gAAAAAgJKCsAUAAAAANiBsAQAAAIANCFsAAAAAYAPCFgAAAADYgLAFAAAAADYgbAEAAACADQhbAAAAAGADwhYAAAAA2ICwBQAAAAA2IGwBAAAAgA0IWwAAAABgA8IWAAAAANiAsAUAAAAANiBsAQAAAIANCFsAAAAAYAPCFgAAAADYwMfTBQAAAJR01cev8ujrp7/Qw6OvD6BgnNkCAAAAABsQtgAAAADABlxGCAAAABSRpy8ZlbhstCThzBYAAAAA2ICwBQAAAAA2IGwBAAAAgA0IWwAAAABgA26QAQBAKebpL/vzRX8AtzLCFgAAALyCp8O/xAEAuBeXEQIAAACADQhbAAAAAGADwhYAAAAA2ICwBQAAAAA2IGwBAAAAgA0IWwAAAABgA8IWAAAAANiAsAUAAAAANiBsAQAAAIANCFsAAAAAYAPCFgAAAADYgLAFAAAAADYgbAEAAACADQhbAAAAAGADwhYAAAAA2ICwBQAAAAA2IGwBAAAAgA0IWwAAAABgA8IWAAAAANiAsAUAAAAANiBsAQAAAIANCFsAAAAAYAPCFgAAAADYgLAFAAAAADYgbAEAAACADQhbAAAAAGCDUhW25syZo9jYWAUEBKhZs2b64osvPF0SAKCUozcBwK2r1IStZcuWKTExURMnTtRXX32le++9V926ddOPP/7o6dIAAKUUvQkAbm2lJmxNnz5dgwYN0mOPPaZ69epp5syZqlq1qubOnevp0gAApRS9CQBubT6eLuBmyMvL044dOzR+/HiX6Z07d9bGjRsLXCY3N1e5ubnW8+zsbElSTk5Oseu4mPu/Yi/rLteqnxqLhhrdgxrd41aosSjLGmPcVY5XoDf9pii1U+O1lYQapVvj84oai+ZWqLEoy16zN5lS4KeffjKSzL///W+X6c8//7ypU6dOgctMmjTJSOLBgwcPHl7yOHTo0M1oGTcNvYkHDx48Sv7jWr2pVJzZusThcLg8N8bkm3bJhAkTNGbMGOv5xYsX9euvvyo0NLTQZeyUk5OjqlWr6tChQ6pQocJNf/1bBfvRPdiP7sO+vDZjjE6ePKno6GhPl2ILehPYj+7BfnQP9mPRFLU3lYqwFRYWprJlyyojI8NlemZmpiIiIgpcxt/fX/7+/i7TKlasaFeJRVahQgXe+G7AfnQP9qP7sC+vzul0eroEt6M34UrsR/dgP7oH+/HaitKbSsUNMvz8/NSsWTOlpqa6TE9NTVXr1q09VBUAoDSjNwHAra9UnNmSpDFjxighIUHNmzdXXFyc5s+frx9//FGPP/64p0sDAJRS9CYAuLWVmrD10EMP6fjx45o8ebKOHDmihg0b6pNPPlFMTIynSysSf39/TZo0Kd/lI7g+7Ef3YD+6D/uydKM3QWI/ugv70T3Yj+7lMOYWu5cuAAAAAHiBUvGdLQAAAAC42QhbAAAAAGADwhYAAAAA2ICwBQAAAAA2IGyVEHPmzFFsbKwCAgLUrFkzffHFF54uqUSZOnWqWrRooeDgYIWHh6t3797av3+/p8sq8aZOnSqHw6HExERPl1Li/PTTT3rkkUcUGhqqcuXKqWnTptqxY4enywKKjL504+hN7kdfujH0JvcjbJUAy5YtU2JioiZOnKivvvpK9957r7p166Yff/zR06WVGBs2bNDw4cO1efNmpaam6vz58+rcubNOnz7t6dJKrG3btmn+/Plq3Lixp0spcbKysnT33XfL19dX//rXv/T111/rlVdeUcWKFT1dGlAk9CX3oDe5F33pxtCb7MGt30uAli1b6s4779TcuXOtafXq1VPv3r01depUD1ZWch07dkzh4eHasGGD7rvvPk+XU+KcOnVKd955p+bMmaPnnntOTZs21cyZMz1dVokxfvx4/fvf/+ZMAEos+pI96E3FR1+6cfQme3Bmy8vl5eVpx44d6ty5s8v0zp07a+PGjR6qquTLzs6WJIWEhHi4kpJp+PDh6tGjhzp27OjpUkqkjz76SM2bN9fvf/97hYeH64477tDrr7/u6bKAIqEv2YfeVHz0pRtHb7IHYcvL/fLLL7pw4YIiIiJcpkdERCgjI8NDVZVsxhiNGTNG99xzjxo2bOjpckqcpUuXaufOnRy9vgHff/+95s6dq9q1a+vTTz/V448/rlGjRumdd97xdGnANdGX7EFvKj76knvQm+zh4+kCUDQOh8PluTEm3zQUzYgRI7Rr1y59+eWXni6lxDl06JBGjx6t1atXKyAgwNPllFgXL15U8+bNNWXKFEnSHXfcob1792ru3Ll69NFHPVwdUDT0JfeiNxUPfcl96E324MyWlwsLC1PZsmXzHS3MzMzMd1QR1zZy5Eh99NFHWrdunapUqeLpckqcHTt2KDMzU82aNZOPj498fHy0YcMG/b//9//k4+OjCxcueLrEEiEqKkr169d3mVavXj1uLoASgb7kfvSm4qMvuQ+9yR6ELS/n5+enZs2aKTU11WV6amqqWrdu7aGqSh5jjEaMGKHly5dr7dq1io2N9XRJJVKHDh20e/dupaWlWY/mzZvrj3/8o9LS0lS2bFlPl1gi3H333flu7/ztt98qJibGQxUBRUdfch96042jL7kPvckeXEZYAowZM0YJCQlq3ry54uLiNH/+fP344496/PHHPV1aiTF8+HAtWbJEH374oYKDg60jsk6nU4GBgR6uruQIDg7O912CoKAghYaG8h2D6/DEE0+odevWmjJlivr27autW7dq/vz5mj9/vqdLA4qEvuQe9KYbR19yH3qTTQxKhNmzZ5uYmBjj5+dn7rzzTrNhwwZPl1SiSCrwsWDBAk+XVuK1adPGjB492tNllDgrV640DRs2NP7+/ub222838+fP93RJwHWhL904epM96EvFR29yP35nCwAAAABswHe2AAAAAMAGhC0AAAAAsAFhCwAAAABsQNgCAAAAABsQtgAAAADABoQtAAAAALABYQsAAAAAbEDYAgAAAAAbELYAAAAAwAaELeAmyMjI0OjRo1WrVi0FBAQoIiJC99xzj+bNm6f//e9/ni6vUNWrV5fD4dDmzZtdpicmJqpt27aeKQoA4Bb0JsB+Pp4uALjVff/997r77rtVsWJFTZkyRY0aNdL58+f17bff6q233lJ0dLR69epV4LLnzp2Tr6/vTa7YVUBAgP76179qw4YNHq0DAOA+9Cbg5uDMFmCzYcOGycfHR9u3b1ffvn1Vr149NWrUSH369NGqVavUs2dPa6zD4dC8efN0//33KygoSM8995wkae7cuapZs6b8/PxUt25dLVy40FomPT1dDodDaWlp1rQTJ07I4XBo/fr1kqT169fL4XBo1apVatKkiQICAtSyZUvt3r37mvUPHTpUmzdv1ieffFLomIsXL2ry5MmqUqWK/P391bRpU6WkpFznngIA3Cz0JuDmIGwBNjp+/LhWr16t4cOHKygoqMAxDofD5fmkSZN0//33a/fu3frTn/6kFStWaPTo0Ro7dqz27NmjoUOHauDAgVq3bt111/OXv/xFL7/8srZt26bw8HD16tVL586du+oy1atX1+OPP64JEybo4sWLBY75+9//rldeeUUvv/yydu3apS5duqhXr146cODAddcIALAXvYnehJvIALDN5s2bjSSzfPlyl+mhoaEmKCjIBAUFmSeffNKaLskkJia6jG3durUZPHiwy7Tf//73pnv37sYYYw4ePGgkma+++sqan5WVZSSZdevWGWOMWbdunZFkli5dao05fvy4CQwMNMuWLSu0/piYGDNjxgyTmZlpgoODzTvvvGOMMWb06NGmTZs21rjo6Gjz/PPPuyzbokULM2zYsELXDQDwDHoTvQk3D2e2gJvgyiOEW7duVVpamho0aKDc3FyXec2bN3d5vm/fPt19990u0+6++27t27fvuuuIi4uz/h0SEqK6desWaT2VK1fWuHHj9Le//U15eXku83JycvTzzz+7rUYAwM1BbwLsR9gCbFSrVi05HA598803LtNr1KihWrVqKTAwMN8yBV3ScWVDNMZY08qUKWNNu+Ral19cbd2FGTNmjM6cOaM5c+YUaT2X1wgA8B70JnoTbh7CFmCj0NBQderUSbNmzdLp06eLtY569erpyy+/dJm2ceNG1atXT9JvR/Yk6ciRI9b8y7+QfLnLb5OblZWlb7/9VrfffnuR6ihfvryeeeYZPf/888rJybGmV6hQQdHR0VetEQDgPehN9CbcPIQtwGZz5szR+fPn1bx5cy1btkz79u3T/v37tWjRIn3zzTcqW7bsVZf/y1/+ouTkZM2bN08HDhzQ9OnTtXz5co0bN06SFBgYqFatWumFF17Q119/rc8//1xPP/10geuaPHmyPvvsM+3Zs0cDBgxQWFiYevfuXeRtGTJkiJxOp9599918Nb744otatmyZ9u/fr/HjxystLU2jR4+WJP3000+6/fbbtXXr1iK/FgDAPvQmehNuEk9+YQwoLX7++WczYsQIExsba3x9fU358uXNXXfdZV566SVz+vRpa5wks2LFinzLz5kzx9SoUcP4+vqaOnXqWF8GvuTrr782rVq1MoGBgaZp06Zm9erVBX4JeeXKlaZBgwbGz8/PtGjRwqSlpV217ktfQr7ckiVLjCSXLyFfuHDBPPvss+a2224zvr6+pkmTJuZf//qXNf/SF6Uv1QMA8Dx6E70J9nMYc9nFtABuSevXr1e7du2UlZWlihUrerocAADoTSgVuIwQAAAAAGxA2AIAAAAAG3AZIQAAAADYgDNbAAAAAGADwhYAAAAA2ICwBQAAAAA2IGwBAAAAgA0IWwAAAABgA8IWAAAAANiAsAUAAAAANiBsAQAAAIAN/j+jZ+nZb0j1QQAAAABJRU5ErkJggg==",
      "text/plain": [
       "<Figure size 1000x500 with 2 Axes>"
      ]
     },
     "metadata": {},
     "output_type": "display_data"
    }
   ],
   "source": [
    "fig, axs = plt.subplots(1, 2, figsize=(10, 5))\n",
    "unique_values_1, counts_1 = np.unique(y_train, return_counts=True)\n",
    "unique_values_2, counts_2 = np.unique(y_test, return_counts=True)\n",
    "\n",
    "plt.subplot(1,2,1)\n",
    "plt.bar(unique_values_1, counts_1)\n",
    "plt.xlabel('Group No.')\n",
    "plt.ylabel('Counts')\n",
    "plt.ylim(bottom = 0, top = 3000)\n",
    "plt.title('Group counts in y_train subset')\n",
    "\n",
    "plt.subplot(1,2,2)\n",
    "plt.bar(unique_values_2, counts_2)\n",
    "plt.xlabel('Group No.')\n",
    "plt.ylabel('Counts')\n",
    "plt.title('Group counts in y_test subset')\n",
    "plt.ylim(bottom = 0, top = 3000)\n",
    "plt.show()"
   ]
  },
  {
   "cell_type": "code",
   "execution_count": 7,
   "metadata": {},
   "outputs": [],
   "source": [
    "oversample = RandomOverSampler(sampling_strategy='minority')"
   ]
  },
  {
   "cell_type": "code",
   "execution_count": 10,
   "metadata": {},
   "outputs": [
    {
     "data": {
      "text/plain": [
       "Counter({6: 2663, 1: 2494, 3: 2316, 7: 1878, 2: 1241, 5: 1136, 0: 974, 4: 971})"
      ]
     },
     "execution_count": 10,
     "metadata": {},
     "output_type": "execute_result"
    }
   ],
   "source": [
    "Counter(y_train)"
   ]
  },
  {
   "cell_type": "code",
   "execution_count": 15,
   "metadata": {},
   "outputs": [
    {
     "data": {
      "text/plain": [
       "Counter({0: 9900, 1: 100})"
      ]
     },
     "execution_count": 15,
     "metadata": {},
     "output_type": "execute_result"
    }
   ],
   "source": [
    "from sklearn.datasets import make_classification\n",
    "X, y = make_classification(n_samples=10000, weights=[0.99], flip_y=0)\n",
    "Counter(y)"
   ]
  },
  {
   "cell_type": "code",
   "execution_count": 11,
   "metadata": {},
   "outputs": [
    {
     "ename": "ValueError",
     "evalue": "Found array with dim 4. None expected <= 2.",
     "output_type": "error",
     "traceback": [
      "\u001b[0;31m---------------------------------------------------------------------------\u001b[0m",
      "\u001b[0;31mValueError\u001b[0m                                Traceback (most recent call last)",
      "\u001b[1;32m/Users/wtc/Documents/USYD/COMP 5318/ASM2/5318ASM2/test.ipynb 单元格 6\u001b[0m line \u001b[0;36m1\n\u001b[0;32m----> <a href='vscode-notebook-cell:/Users/wtc/Documents/USYD/COMP%205318/ASM2/5318ASM2/test.ipynb#W5sZmlsZQ%3D%3D?line=0'>1</a>\u001b[0m X_over, y_over \u001b[39m=\u001b[39m oversample\u001b[39m.\u001b[39;49mfit_resample(X_train, y_train)\n",
      "File \u001b[0;32m~/anaconda3/envs/tf-metal/lib/python3.10/site-packages/imblearn/base.py:208\u001b[0m, in \u001b[0;36mBaseSampler.fit_resample\u001b[0;34m(self, X, y)\u001b[0m\n\u001b[1;32m    187\u001b[0m \u001b[39m\u001b[39m\u001b[39m\"\"\"Resample the dataset.\u001b[39;00m\n\u001b[1;32m    188\u001b[0m \n\u001b[1;32m    189\u001b[0m \u001b[39mParameters\u001b[39;00m\n\u001b[0;32m   (...)\u001b[0m\n\u001b[1;32m    205\u001b[0m \u001b[39m    The corresponding label of `X_resampled`.\u001b[39;00m\n\u001b[1;32m    206\u001b[0m \u001b[39m\"\"\"\u001b[39;00m\n\u001b[1;32m    207\u001b[0m \u001b[39mself\u001b[39m\u001b[39m.\u001b[39m_validate_params()\n\u001b[0;32m--> 208\u001b[0m \u001b[39mreturn\u001b[39;00m \u001b[39msuper\u001b[39;49m()\u001b[39m.\u001b[39;49mfit_resample(X, y)\n",
      "File \u001b[0;32m~/anaconda3/envs/tf-metal/lib/python3.10/site-packages/imblearn/base.py:106\u001b[0m, in \u001b[0;36mSamplerMixin.fit_resample\u001b[0;34m(self, X, y)\u001b[0m\n\u001b[1;32m    104\u001b[0m check_classification_targets(y)\n\u001b[1;32m    105\u001b[0m arrays_transformer \u001b[39m=\u001b[39m ArraysTransformer(X, y)\n\u001b[0;32m--> 106\u001b[0m X, y, binarize_y \u001b[39m=\u001b[39m \u001b[39mself\u001b[39;49m\u001b[39m.\u001b[39;49m_check_X_y(X, y)\n\u001b[1;32m    108\u001b[0m \u001b[39mself\u001b[39m\u001b[39m.\u001b[39msampling_strategy_ \u001b[39m=\u001b[39m check_sampling_strategy(\n\u001b[1;32m    109\u001b[0m     \u001b[39mself\u001b[39m\u001b[39m.\u001b[39msampling_strategy, y, \u001b[39mself\u001b[39m\u001b[39m.\u001b[39m_sampling_type\n\u001b[1;32m    110\u001b[0m )\n\u001b[1;32m    112\u001b[0m output \u001b[39m=\u001b[39m \u001b[39mself\u001b[39m\u001b[39m.\u001b[39m_fit_resample(X, y)\n",
      "File \u001b[0;32m~/anaconda3/envs/tf-metal/lib/python3.10/site-packages/imblearn/over_sampling/_random_over_sampler.py:158\u001b[0m, in \u001b[0;36mRandomOverSampler._check_X_y\u001b[0;34m(self, X, y)\u001b[0m\n\u001b[1;32m    156\u001b[0m \u001b[39mdef\u001b[39;00m \u001b[39m_check_X_y\u001b[39m(\u001b[39mself\u001b[39m, X, y):\n\u001b[1;32m    157\u001b[0m     y, binarize_y \u001b[39m=\u001b[39m check_target_type(y, indicate_one_vs_all\u001b[39m=\u001b[39m\u001b[39mTrue\u001b[39;00m)\n\u001b[0;32m--> 158\u001b[0m     X \u001b[39m=\u001b[39m _check_X(X)\n\u001b[1;32m    159\u001b[0m     \u001b[39mself\u001b[39m\u001b[39m.\u001b[39m_check_n_features(X, reset\u001b[39m=\u001b[39m\u001b[39mTrue\u001b[39;00m)\n\u001b[1;32m    160\u001b[0m     \u001b[39mself\u001b[39m\u001b[39m.\u001b[39m_check_feature_names(X, reset\u001b[39m=\u001b[39m\u001b[39mTrue\u001b[39;00m)\n",
      "File \u001b[0;32m~/anaconda3/envs/tf-metal/lib/python3.10/site-packages/imblearn/utils/_validation.py:624\u001b[0m, in \u001b[0;36m_check_X\u001b[0;34m(X)\u001b[0m\n\u001b[1;32m    622\u001b[0m \u001b[39mif\u001b[39;00m _is_pandas_df(X):\n\u001b[1;32m    623\u001b[0m     \u001b[39mreturn\u001b[39;00m X\n\u001b[0;32m--> 624\u001b[0m \u001b[39mreturn\u001b[39;00m check_array(\n\u001b[1;32m    625\u001b[0m     X, dtype\u001b[39m=\u001b[39;49m\u001b[39mNone\u001b[39;49;00m, accept_sparse\u001b[39m=\u001b[39;49m[\u001b[39m\"\u001b[39;49m\u001b[39mcsr\u001b[39;49m\u001b[39m\"\u001b[39;49m, \u001b[39m\"\u001b[39;49m\u001b[39mcsc\u001b[39;49m\u001b[39m\"\u001b[39;49m], force_all_finite\u001b[39m=\u001b[39;49m\u001b[39mFalse\u001b[39;49;00m\n\u001b[1;32m    626\u001b[0m )\n",
      "File \u001b[0;32m~/anaconda3/envs/tf-metal/lib/python3.10/site-packages/sklearn/utils/validation.py:953\u001b[0m, in \u001b[0;36mcheck_array\u001b[0;34m(array, accept_sparse, accept_large_sparse, dtype, order, copy, force_all_finite, ensure_2d, allow_nd, ensure_min_samples, ensure_min_features, estimator, input_name)\u001b[0m\n\u001b[1;32m    948\u001b[0m     \u001b[39mraise\u001b[39;00m \u001b[39mValueError\u001b[39;00m(\n\u001b[1;32m    949\u001b[0m         \u001b[39m\"\u001b[39m\u001b[39mdtype=\u001b[39m\u001b[39m'\u001b[39m\u001b[39mnumeric\u001b[39m\u001b[39m'\u001b[39m\u001b[39m is not compatible with arrays of bytes/strings.\u001b[39m\u001b[39m\"\u001b[39m\n\u001b[1;32m    950\u001b[0m         \u001b[39m\"\u001b[39m\u001b[39mConvert your data to numeric values explicitly instead.\u001b[39m\u001b[39m\"\u001b[39m\n\u001b[1;32m    951\u001b[0m     )\n\u001b[1;32m    952\u001b[0m \u001b[39mif\u001b[39;00m \u001b[39mnot\u001b[39;00m allow_nd \u001b[39mand\u001b[39;00m array\u001b[39m.\u001b[39mndim \u001b[39m>\u001b[39m\u001b[39m=\u001b[39m \u001b[39m3\u001b[39m:\n\u001b[0;32m--> 953\u001b[0m     \u001b[39mraise\u001b[39;00m \u001b[39mValueError\u001b[39;00m(\n\u001b[1;32m    954\u001b[0m         \u001b[39m\"\u001b[39m\u001b[39mFound array with dim \u001b[39m\u001b[39m%d\u001b[39;00m\u001b[39m. \u001b[39m\u001b[39m%s\u001b[39;00m\u001b[39m expected <= 2.\u001b[39m\u001b[39m\"\u001b[39m\n\u001b[1;32m    955\u001b[0m         \u001b[39m%\u001b[39m (array\u001b[39m.\u001b[39mndim, estimator_name)\n\u001b[1;32m    956\u001b[0m     )\n\u001b[1;32m    958\u001b[0m \u001b[39mif\u001b[39;00m force_all_finite:\n\u001b[1;32m    959\u001b[0m     _assert_all_finite(\n\u001b[1;32m    960\u001b[0m         array,\n\u001b[1;32m    961\u001b[0m         input_name\u001b[39m=\u001b[39minput_name,\n\u001b[1;32m    962\u001b[0m         estimator_name\u001b[39m=\u001b[39mestimator_name,\n\u001b[1;32m    963\u001b[0m         allow_nan\u001b[39m=\u001b[39mforce_all_finite \u001b[39m==\u001b[39m \u001b[39m\"\u001b[39m\u001b[39mallow-nan\u001b[39m\u001b[39m\"\u001b[39m,\n\u001b[1;32m    964\u001b[0m     )\n",
      "\u001b[0;31mValueError\u001b[0m: Found array with dim 4. None expected <= 2."
     ]
    }
   ],
   "source": [
    "X_over, y_over = oversample.fit_resample(X_train, y_train)"
   ]
  },
  {
   "cell_type": "code",
   "execution_count": 19,
   "metadata": {},
   "outputs": [
    {
     "data": {
      "text/plain": [
       "974"
      ]
     },
     "execution_count": 19,
     "metadata": {},
     "output_type": "execute_result"
    }
   ],
   "source": [
    "class_1 = X_train[y_train==0]\n",
    "len(class_1)"
   ]
  },
  {
   "cell_type": "code",
   "execution_count": null,
   "metadata": {},
   "outputs": [],
   "source": [
    "##Random forest ensemble method\n",
    "from sklearn.ensemble import RandomForestClassifier\n",
    "model_rf = RandomForestClassifier()\n",
    "model.fit(x_train2,y_train)"
   ]
  },
  {
   "cell_type": "code",
   "execution_count": 25,
   "metadata": {},
   "outputs": [],
   "source": [
    "X_train_r =  np.reshape(X_train, (X_train.shape[0], -1))\n",
    "X_test_r = np.reshape(X_test, (X_test.shape[0], -1))\n",
    "\n",
    "X_train_r_n =  X_train_r/255.0\n",
    "X_test_r_n = X_test_r/255.0"
   ]
  },
  {
   "cell_type": "code",
   "execution_count": 26,
   "metadata": {},
   "outputs": [
    {
     "name": "stderr",
     "output_type": "stream",
     "text": [
      "/Users/wtc/anaconda3/envs/tf-metal/lib/python3.10/site-packages/sklearn/neural_network/_multilayer_perceptron.py:691: ConvergenceWarning: Stochastic Optimizer: Maximum iterations (10) reached and the optimization hasn't converged yet.\n",
      "  warnings.warn(\n",
      "/Users/wtc/anaconda3/envs/tf-metal/lib/python3.10/site-packages/sklearn/neural_network/_multilayer_perceptron.py:691: ConvergenceWarning: Stochastic Optimizer: Maximum iterations (10) reached and the optimization hasn't converged yet.\n",
      "  warnings.warn(\n",
      "/Users/wtc/anaconda3/envs/tf-metal/lib/python3.10/site-packages/sklearn/neural_network/_multilayer_perceptron.py:691: ConvergenceWarning: Stochastic Optimizer: Maximum iterations (10) reached and the optimization hasn't converged yet.\n",
      "  warnings.warn(\n",
      "/Users/wtc/anaconda3/envs/tf-metal/lib/python3.10/site-packages/sklearn/neural_network/_multilayer_perceptron.py:691: ConvergenceWarning: Stochastic Optimizer: Maximum iterations (10) reached and the optimization hasn't converged yet.\n",
      "  warnings.warn(\n",
      "/Users/wtc/anaconda3/envs/tf-metal/lib/python3.10/site-packages/sklearn/neural_network/_multilayer_perceptron.py:691: ConvergenceWarning: Stochastic Optimizer: Maximum iterations (10) reached and the optimization hasn't converged yet.\n",
      "  warnings.warn(\n",
      "/Users/wtc/anaconda3/envs/tf-metal/lib/python3.10/site-packages/sklearn/neural_network/_multilayer_perceptron.py:691: ConvergenceWarning: Stochastic Optimizer: Maximum iterations (10) reached and the optimization hasn't converged yet.\n",
      "  warnings.warn(\n",
      "/Users/wtc/anaconda3/envs/tf-metal/lib/python3.10/site-packages/sklearn/neural_network/_multilayer_perceptron.py:691: ConvergenceWarning: Stochastic Optimizer: Maximum iterations (10) reached and the optimization hasn't converged yet.\n",
      "  warnings.warn(\n",
      "/Users/wtc/anaconda3/envs/tf-metal/lib/python3.10/site-packages/sklearn/neural_network/_multilayer_perceptron.py:691: ConvergenceWarning: Stochastic Optimizer: Maximum iterations (10) reached and the optimization hasn't converged yet.\n",
      "  warnings.warn(\n",
      "/Users/wtc/anaconda3/envs/tf-metal/lib/python3.10/site-packages/sklearn/neural_network/_multilayer_perceptron.py:691: ConvergenceWarning: Stochastic Optimizer: Maximum iterations (10) reached and the optimization hasn't converged yet.\n",
      "  warnings.warn(\n",
      "/Users/wtc/anaconda3/envs/tf-metal/lib/python3.10/site-packages/sklearn/neural_network/_multilayer_perceptron.py:691: ConvergenceWarning: Stochastic Optimizer: Maximum iterations (10) reached and the optimization hasn't converged yet.\n",
      "  warnings.warn(\n",
      "/Users/wtc/anaconda3/envs/tf-metal/lib/python3.10/site-packages/sklearn/neural_network/_multilayer_perceptron.py:691: ConvergenceWarning: Stochastic Optimizer: Maximum iterations (10) reached and the optimization hasn't converged yet.\n",
      "  warnings.warn(\n",
      "/Users/wtc/anaconda3/envs/tf-metal/lib/python3.10/site-packages/sklearn/neural_network/_multilayer_perceptron.py:691: ConvergenceWarning: Stochastic Optimizer: Maximum iterations (10) reached and the optimization hasn't converged yet.\n",
      "  warnings.warn(\n",
      "/Users/wtc/anaconda3/envs/tf-metal/lib/python3.10/site-packages/sklearn/neural_network/_multilayer_perceptron.py:691: ConvergenceWarning: Stochastic Optimizer: Maximum iterations (10) reached and the optimization hasn't converged yet.\n",
      "  warnings.warn(\n",
      "/Users/wtc/anaconda3/envs/tf-metal/lib/python3.10/site-packages/sklearn/neural_network/_multilayer_perceptron.py:691: ConvergenceWarning: Stochastic Optimizer: Maximum iterations (10) reached and the optimization hasn't converged yet.\n",
      "  warnings.warn(\n",
      "/Users/wtc/anaconda3/envs/tf-metal/lib/python3.10/site-packages/sklearn/neural_network/_multilayer_perceptron.py:691: ConvergenceWarning: Stochastic Optimizer: Maximum iterations (10) reached and the optimization hasn't converged yet.\n",
      "  warnings.warn(\n",
      "/Users/wtc/anaconda3/envs/tf-metal/lib/python3.10/site-packages/sklearn/neural_network/_multilayer_perceptron.py:691: ConvergenceWarning: Stochastic Optimizer: Maximum iterations (10) reached and the optimization hasn't converged yet.\n",
      "  warnings.warn(\n",
      "/Users/wtc/anaconda3/envs/tf-metal/lib/python3.10/site-packages/sklearn/neural_network/_multilayer_perceptron.py:691: ConvergenceWarning: Stochastic Optimizer: Maximum iterations (10) reached and the optimization hasn't converged yet.\n",
      "  warnings.warn(\n",
      "/Users/wtc/anaconda3/envs/tf-metal/lib/python3.10/site-packages/sklearn/neural_network/_multilayer_perceptron.py:691: ConvergenceWarning: Stochastic Optimizer: Maximum iterations (10) reached and the optimization hasn't converged yet.\n",
      "  warnings.warn(\n"
     ]
    },
    {
     "name": "stdout",
     "output_type": "stream",
     "text": [
      "Best parameters found:\n",
      " {'activation': 'relu', 'alpha': 0.05, 'hidden_layer_sizes': (50, 100, 50), 'learning_rate': 'adaptive', 'solver': 'adam'}\n",
      "0.732 (+/-0.046) for {'activation': 'relu', 'alpha': 0.05, 'hidden_layer_sizes': (50, 50, 50), 'learning_rate': 'constant', 'solver': 'adam'}\n",
      "0.729 (+/-0.043) for {'activation': 'relu', 'alpha': 0.05, 'hidden_layer_sizes': (50, 50, 50), 'learning_rate': 'adaptive', 'solver': 'adam'}\n",
      "0.743 (+/-0.037) for {'activation': 'relu', 'alpha': 0.05, 'hidden_layer_sizes': (50, 100, 50), 'learning_rate': 'constant', 'solver': 'adam'}\n",
      "0.750 (+/-0.006) for {'activation': 'relu', 'alpha': 0.05, 'hidden_layer_sizes': (50, 100, 50), 'learning_rate': 'adaptive', 'solver': 'adam'}\n",
      "0.735 (+/-0.035) for {'activation': 'relu', 'alpha': 0.05, 'hidden_layer_sizes': (100,), 'learning_rate': 'constant', 'solver': 'adam'}\n",
      "0.741 (+/-0.012) for {'activation': 'relu', 'alpha': 0.05, 'hidden_layer_sizes': (100,), 'learning_rate': 'adaptive', 'solver': 'adam'}\n"
     ]
    }
   ],
   "source": [
    "from sklearn.neural_network import MLPClassifier\n",
    "import warnings\n",
    "warnings.filterwarnings(\"ignore\")\n",
    "mlp = MLPClassifier(max_iter=10)\n",
    "parameter_space = {\n",
    "    'hidden_layer_sizes': [(32,), (32,16), (128,3)],\n",
    "    'activation': ['relu'],\n",
    "    'solver': ['adam'],\n",
    "    'alpha': [0.05],\n",
    "    'learning_rate': ['constant','adaptive'],\n",
    "}\n",
    "\n",
    "from sklearn.model_selection import GridSearchCV\n",
    "\n",
    "clf = GridSearchCV(mlp, parameter_space, n_jobs=-1, cv=3)\n",
    "clf.fit(X_train_r_n, y_train)\n",
    "\n",
    "# Best paramete set\n",
    "print('Best parameters found:\\n', clf.best_params_)\n",
    "\n",
    "# All results\n",
    "means = clf.cv_results_['mean_test_score']\n",
    "stds = clf.cv_results_['std_test_score']\n",
    "for mean, std, params in zip(means, stds, clf.cv_results_['params']):\n",
    "    print(\"%0.3f (+/-%0.03f) for %r\" % (mean, std * 2, params))"
   ]
  },
  {
   "cell_type": "code",
   "execution_count": 21,
   "metadata": {},
   "outputs": [
    {
     "ename": "ValueError",
     "evalue": "\nAll the 12 fits failed.\nIt is very likely that your model is misconfigured.\nYou can try to debug the error by setting error_score='raise'.\n\nBelow are more details about the failures:\n--------------------------------------------------------------------------------\n2 fits failed with the following error:\nTraceback (most recent call last):\n  File \"/Users/wtc/anaconda3/envs/tf-metal/lib/python3.10/site-packages/sklearn/model_selection/_validation.py\", line 732, in _fit_and_score\n    estimator.fit(X_train, y_train, **fit_params)\n  File \"/Users/wtc/anaconda3/envs/tf-metal/lib/python3.10/site-packages/scikeras/wrappers.py\", line 1491, in fit\n    super().fit(X=X, y=y, sample_weight=sample_weight, **kwargs)\n  File \"/Users/wtc/anaconda3/envs/tf-metal/lib/python3.10/site-packages/scikeras/wrappers.py\", line 760, in fit\n    self._fit(\n  File \"/Users/wtc/anaconda3/envs/tf-metal/lib/python3.10/site-packages/scikeras/wrappers.py\", line 928, in _fit\n    self._fit_keras_model(\n  File \"/Users/wtc/anaconda3/envs/tf-metal/lib/python3.10/site-packages/scikeras/wrappers.py\", line 524, in _fit_keras_model\n    hist = self.model_.fit(x=X, y=y, **fit_args)\n  File \"/Users/wtc/anaconda3/envs/tf-metal/lib/python3.10/site-packages/keras/src/utils/traceback_utils.py\", line 70, in error_handler\n    raise e.with_traceback(filtered_tb) from None\n  File \"/var/folders/4w/p3jk6v8j135cv56t4gzkzv3r0000gn/T/__autograph_generated_filemf5ei3g5.py\", line 15, in tf__train_function\n    retval_ = ag__.converted_call(ag__.ld(step_function), (ag__.ld(self), ag__.ld(iterator)), None, fscope)\nValueError: in user code:\n\n    File \"/Users/wtc/anaconda3/envs/tf-metal/lib/python3.10/site-packages/keras/src/engine/training.py\", line 1338, in train_function  *\n        return step_function(self, iterator)\n    File \"/Users/wtc/anaconda3/envs/tf-metal/lib/python3.10/site-packages/keras/src/engine/training.py\", line 1322, in step_function  **\n        outputs = model.distribute_strategy.run(run_step, args=(data,))\n    File \"/Users/wtc/anaconda3/envs/tf-metal/lib/python3.10/site-packages/keras/src/engine/training.py\", line 1303, in run_step  **\n        outputs = model.train_step(data)\n    File \"/Users/wtc/anaconda3/envs/tf-metal/lib/python3.10/site-packages/keras/src/engine/training.py\", line 1081, in train_step\n        loss = self.compute_loss(x, y, y_pred, sample_weight)\n    File \"/Users/wtc/anaconda3/envs/tf-metal/lib/python3.10/site-packages/keras/src/engine/training.py\", line 1139, in compute_loss\n        return self.compiled_loss(\n    File \"/Users/wtc/anaconda3/envs/tf-metal/lib/python3.10/site-packages/keras/src/engine/compile_utils.py\", line 265, in __call__\n        loss_value = loss_obj(y_t, y_p, sample_weight=sw)\n    File \"/Users/wtc/anaconda3/envs/tf-metal/lib/python3.10/site-packages/keras/src/losses.py\", line 142, in __call__\n        losses = call_fn(y_true, y_pred)\n    File \"/Users/wtc/anaconda3/envs/tf-metal/lib/python3.10/site-packages/keras/src/losses.py\", line 268, in call  **\n        return ag_fn(y_true, y_pred, **self._fn_kwargs)\n    File \"/Users/wtc/anaconda3/envs/tf-metal/lib/python3.10/site-packages/keras/src/losses.py\", line 2122, in categorical_crossentropy\n        return backend.categorical_crossentropy(\n    File \"/Users/wtc/anaconda3/envs/tf-metal/lib/python3.10/site-packages/keras/src/backend.py\", line 5560, in categorical_crossentropy\n        target.shape.assert_is_compatible_with(output.shape)\n\n    ValueError: Shapes (None, 8) and (None, 28, 28, 8) are incompatible\n\n\n--------------------------------------------------------------------------------\n1 fits failed with the following error:\nTraceback (most recent call last):\n  File \"/Users/wtc/anaconda3/envs/tf-metal/lib/python3.10/site-packages/sklearn/model_selection/_validation.py\", line 732, in _fit_and_score\n    estimator.fit(X_train, y_train, **fit_params)\n  File \"/Users/wtc/anaconda3/envs/tf-metal/lib/python3.10/site-packages/scikeras/wrappers.py\", line 1491, in fit\n    super().fit(X=X, y=y, sample_weight=sample_weight, **kwargs)\n  File \"/Users/wtc/anaconda3/envs/tf-metal/lib/python3.10/site-packages/scikeras/wrappers.py\", line 760, in fit\n    self._fit(\n  File \"/Users/wtc/anaconda3/envs/tf-metal/lib/python3.10/site-packages/scikeras/wrappers.py\", line 928, in _fit\n    self._fit_keras_model(\n  File \"/Users/wtc/anaconda3/envs/tf-metal/lib/python3.10/site-packages/scikeras/wrappers.py\", line 524, in _fit_keras_model\n    hist = self.model_.fit(x=X, y=y, **fit_args)\n  File \"/Users/wtc/anaconda3/envs/tf-metal/lib/python3.10/site-packages/keras/src/utils/traceback_utils.py\", line 70, in error_handler\n    raise e.with_traceback(filtered_tb) from None\n  File \"/var/folders/4w/p3jk6v8j135cv56t4gzkzv3r0000gn/T/__autograph_generated_filee168y96t.py\", line 15, in tf__train_function\n    retval_ = ag__.converted_call(ag__.ld(step_function), (ag__.ld(self), ag__.ld(iterator)), None, fscope)\nValueError: in user code:\n\n    File \"/Users/wtc/anaconda3/envs/tf-metal/lib/python3.10/site-packages/keras/src/engine/training.py\", line 1338, in train_function  *\n        return step_function(self, iterator)\n    File \"/Users/wtc/anaconda3/envs/tf-metal/lib/python3.10/site-packages/keras/src/engine/training.py\", line 1322, in step_function  **\n        outputs = model.distribute_strategy.run(run_step, args=(data,))\n    File \"/Users/wtc/anaconda3/envs/tf-metal/lib/python3.10/site-packages/keras/src/engine/training.py\", line 1303, in run_step  **\n        outputs = model.train_step(data)\n    File \"/Users/wtc/anaconda3/envs/tf-metal/lib/python3.10/site-packages/keras/src/engine/training.py\", line 1081, in train_step\n        loss = self.compute_loss(x, y, y_pred, sample_weight)\n    File \"/Users/wtc/anaconda3/envs/tf-metal/lib/python3.10/site-packages/keras/src/engine/training.py\", line 1139, in compute_loss\n        return self.compiled_loss(\n    File \"/Users/wtc/anaconda3/envs/tf-metal/lib/python3.10/site-packages/keras/src/engine/compile_utils.py\", line 265, in __call__\n        loss_value = loss_obj(y_t, y_p, sample_weight=sw)\n    File \"/Users/wtc/anaconda3/envs/tf-metal/lib/python3.10/site-packages/keras/src/losses.py\", line 142, in __call__\n        losses = call_fn(y_true, y_pred)\n    File \"/Users/wtc/anaconda3/envs/tf-metal/lib/python3.10/site-packages/keras/src/losses.py\", line 268, in call  **\n        return ag_fn(y_true, y_pred, **self._fn_kwargs)\n    File \"/Users/wtc/anaconda3/envs/tf-metal/lib/python3.10/site-packages/keras/src/losses.py\", line 2122, in categorical_crossentropy\n        return backend.categorical_crossentropy(\n    File \"/Users/wtc/anaconda3/envs/tf-metal/lib/python3.10/site-packages/keras/src/backend.py\", line 5560, in categorical_crossentropy\n        target.shape.assert_is_compatible_with(output.shape)\n\n    ValueError: Shapes (None, 8) and (None, 28, 28, 8) are incompatible\n\n\n--------------------------------------------------------------------------------\n2 fits failed with the following error:\nTraceback (most recent call last):\n  File \"/Users/wtc/anaconda3/envs/tf-metal/lib/python3.10/site-packages/sklearn/model_selection/_validation.py\", line 732, in _fit_and_score\n    estimator.fit(X_train, y_train, **fit_params)\n  File \"/Users/wtc/anaconda3/envs/tf-metal/lib/python3.10/site-packages/scikeras/wrappers.py\", line 1491, in fit\n    super().fit(X=X, y=y, sample_weight=sample_weight, **kwargs)\n  File \"/Users/wtc/anaconda3/envs/tf-metal/lib/python3.10/site-packages/scikeras/wrappers.py\", line 760, in fit\n    self._fit(\n  File \"/Users/wtc/anaconda3/envs/tf-metal/lib/python3.10/site-packages/scikeras/wrappers.py\", line 928, in _fit\n    self._fit_keras_model(\n  File \"/Users/wtc/anaconda3/envs/tf-metal/lib/python3.10/site-packages/scikeras/wrappers.py\", line 524, in _fit_keras_model\n    hist = self.model_.fit(x=X, y=y, **fit_args)\n  File \"/Users/wtc/anaconda3/envs/tf-metal/lib/python3.10/site-packages/keras/src/utils/traceback_utils.py\", line 70, in error_handler\n    raise e.with_traceback(filtered_tb) from None\n  File \"/var/folders/4w/p3jk6v8j135cv56t4gzkzv3r0000gn/T/__autograph_generated_fileuncpeb_n.py\", line 15, in tf__train_function\n    retval_ = ag__.converted_call(ag__.ld(step_function), (ag__.ld(self), ag__.ld(iterator)), None, fscope)\nValueError: in user code:\n\n    File \"/Users/wtc/anaconda3/envs/tf-metal/lib/python3.10/site-packages/keras/src/engine/training.py\", line 1338, in train_function  *\n        return step_function(self, iterator)\n    File \"/Users/wtc/anaconda3/envs/tf-metal/lib/python3.10/site-packages/keras/src/engine/training.py\", line 1322, in step_function  **\n        outputs = model.distribute_strategy.run(run_step, args=(data,))\n    File \"/Users/wtc/anaconda3/envs/tf-metal/lib/python3.10/site-packages/keras/src/engine/training.py\", line 1303, in run_step  **\n        outputs = model.train_step(data)\n    File \"/Users/wtc/anaconda3/envs/tf-metal/lib/python3.10/site-packages/keras/src/engine/training.py\", line 1081, in train_step\n        loss = self.compute_loss(x, y, y_pred, sample_weight)\n    File \"/Users/wtc/anaconda3/envs/tf-metal/lib/python3.10/site-packages/keras/src/engine/training.py\", line 1139, in compute_loss\n        return self.compiled_loss(\n    File \"/Users/wtc/anaconda3/envs/tf-metal/lib/python3.10/site-packages/keras/src/engine/compile_utils.py\", line 265, in __call__\n        loss_value = loss_obj(y_t, y_p, sample_weight=sw)\n    File \"/Users/wtc/anaconda3/envs/tf-metal/lib/python3.10/site-packages/keras/src/losses.py\", line 142, in __call__\n        losses = call_fn(y_true, y_pred)\n    File \"/Users/wtc/anaconda3/envs/tf-metal/lib/python3.10/site-packages/keras/src/losses.py\", line 268, in call  **\n        return ag_fn(y_true, y_pred, **self._fn_kwargs)\n    File \"/Users/wtc/anaconda3/envs/tf-metal/lib/python3.10/site-packages/keras/src/losses.py\", line 2122, in categorical_crossentropy\n        return backend.categorical_crossentropy(\n    File \"/Users/wtc/anaconda3/envs/tf-metal/lib/python3.10/site-packages/keras/src/backend.py\", line 5560, in categorical_crossentropy\n        target.shape.assert_is_compatible_with(output.shape)\n\n    ValueError: Shapes (None, 8) and (None, 28, 28, 8) are incompatible\n\n\n--------------------------------------------------------------------------------\n1 fits failed with the following error:\nTraceback (most recent call last):\n  File \"/Users/wtc/anaconda3/envs/tf-metal/lib/python3.10/site-packages/sklearn/model_selection/_validation.py\", line 732, in _fit_and_score\n    estimator.fit(X_train, y_train, **fit_params)\n  File \"/Users/wtc/anaconda3/envs/tf-metal/lib/python3.10/site-packages/scikeras/wrappers.py\", line 1491, in fit\n    super().fit(X=X, y=y, sample_weight=sample_weight, **kwargs)\n  File \"/Users/wtc/anaconda3/envs/tf-metal/lib/python3.10/site-packages/scikeras/wrappers.py\", line 760, in fit\n    self._fit(\n  File \"/Users/wtc/anaconda3/envs/tf-metal/lib/python3.10/site-packages/scikeras/wrappers.py\", line 928, in _fit\n    self._fit_keras_model(\n  File \"/Users/wtc/anaconda3/envs/tf-metal/lib/python3.10/site-packages/scikeras/wrappers.py\", line 524, in _fit_keras_model\n    hist = self.model_.fit(x=X, y=y, **fit_args)\n  File \"/Users/wtc/anaconda3/envs/tf-metal/lib/python3.10/site-packages/keras/src/utils/traceback_utils.py\", line 70, in error_handler\n    raise e.with_traceback(filtered_tb) from None\n  File \"/var/folders/4w/p3jk6v8j135cv56t4gzkzv3r0000gn/T/__autograph_generated_fileuq0c4ggh.py\", line 15, in tf__train_function\n    retval_ = ag__.converted_call(ag__.ld(step_function), (ag__.ld(self), ag__.ld(iterator)), None, fscope)\nValueError: in user code:\n\n    File \"/Users/wtc/anaconda3/envs/tf-metal/lib/python3.10/site-packages/keras/src/engine/training.py\", line 1338, in train_function  *\n        return step_function(self, iterator)\n    File \"/Users/wtc/anaconda3/envs/tf-metal/lib/python3.10/site-packages/keras/src/engine/training.py\", line 1322, in step_function  **\n        outputs = model.distribute_strategy.run(run_step, args=(data,))\n    File \"/Users/wtc/anaconda3/envs/tf-metal/lib/python3.10/site-packages/keras/src/engine/training.py\", line 1303, in run_step  **\n        outputs = model.train_step(data)\n    File \"/Users/wtc/anaconda3/envs/tf-metal/lib/python3.10/site-packages/keras/src/engine/training.py\", line 1081, in train_step\n        loss = self.compute_loss(x, y, y_pred, sample_weight)\n    File \"/Users/wtc/anaconda3/envs/tf-metal/lib/python3.10/site-packages/keras/src/engine/training.py\", line 1139, in compute_loss\n        return self.compiled_loss(\n    File \"/Users/wtc/anaconda3/envs/tf-metal/lib/python3.10/site-packages/keras/src/engine/compile_utils.py\", line 265, in __call__\n        loss_value = loss_obj(y_t, y_p, sample_weight=sw)\n    File \"/Users/wtc/anaconda3/envs/tf-metal/lib/python3.10/site-packages/keras/src/losses.py\", line 142, in __call__\n        losses = call_fn(y_true, y_pred)\n    File \"/Users/wtc/anaconda3/envs/tf-metal/lib/python3.10/site-packages/keras/src/losses.py\", line 268, in call  **\n        return ag_fn(y_true, y_pred, **self._fn_kwargs)\n    File \"/Users/wtc/anaconda3/envs/tf-metal/lib/python3.10/site-packages/keras/src/losses.py\", line 2122, in categorical_crossentropy\n        return backend.categorical_crossentropy(\n    File \"/Users/wtc/anaconda3/envs/tf-metal/lib/python3.10/site-packages/keras/src/backend.py\", line 5560, in categorical_crossentropy\n        target.shape.assert_is_compatible_with(output.shape)\n\n    ValueError: Shapes (None, 8) and (None, 28, 28, 8) are incompatible\n\n\n--------------------------------------------------------------------------------\n2 fits failed with the following error:\nTraceback (most recent call last):\n  File \"/Users/wtc/anaconda3/envs/tf-metal/lib/python3.10/site-packages/sklearn/model_selection/_validation.py\", line 732, in _fit_and_score\n    estimator.fit(X_train, y_train, **fit_params)\n  File \"/Users/wtc/anaconda3/envs/tf-metal/lib/python3.10/site-packages/scikeras/wrappers.py\", line 1491, in fit\n    super().fit(X=X, y=y, sample_weight=sample_weight, **kwargs)\n  File \"/Users/wtc/anaconda3/envs/tf-metal/lib/python3.10/site-packages/scikeras/wrappers.py\", line 760, in fit\n    self._fit(\n  File \"/Users/wtc/anaconda3/envs/tf-metal/lib/python3.10/site-packages/scikeras/wrappers.py\", line 928, in _fit\n    self._fit_keras_model(\n  File \"/Users/wtc/anaconda3/envs/tf-metal/lib/python3.10/site-packages/scikeras/wrappers.py\", line 524, in _fit_keras_model\n    hist = self.model_.fit(x=X, y=y, **fit_args)\n  File \"/Users/wtc/anaconda3/envs/tf-metal/lib/python3.10/site-packages/keras/src/utils/traceback_utils.py\", line 70, in error_handler\n    raise e.with_traceback(filtered_tb) from None\n  File \"/var/folders/4w/p3jk6v8j135cv56t4gzkzv3r0000gn/T/__autograph_generated_filei1ufkfiy.py\", line 15, in tf__train_function\n    retval_ = ag__.converted_call(ag__.ld(step_function), (ag__.ld(self), ag__.ld(iterator)), None, fscope)\nValueError: in user code:\n\n    File \"/Users/wtc/anaconda3/envs/tf-metal/lib/python3.10/site-packages/keras/src/engine/training.py\", line 1338, in train_function  *\n        return step_function(self, iterator)\n    File \"/Users/wtc/anaconda3/envs/tf-metal/lib/python3.10/site-packages/keras/src/engine/training.py\", line 1322, in step_function  **\n        outputs = model.distribute_strategy.run(run_step, args=(data,))\n    File \"/Users/wtc/anaconda3/envs/tf-metal/lib/python3.10/site-packages/keras/src/engine/training.py\", line 1303, in run_step  **\n        outputs = model.train_step(data)\n    File \"/Users/wtc/anaconda3/envs/tf-metal/lib/python3.10/site-packages/keras/src/engine/training.py\", line 1081, in train_step\n        loss = self.compute_loss(x, y, y_pred, sample_weight)\n    File \"/Users/wtc/anaconda3/envs/tf-metal/lib/python3.10/site-packages/keras/src/engine/training.py\", line 1139, in compute_loss\n        return self.compiled_loss(\n    File \"/Users/wtc/anaconda3/envs/tf-metal/lib/python3.10/site-packages/keras/src/engine/compile_utils.py\", line 265, in __call__\n        loss_value = loss_obj(y_t, y_p, sample_weight=sw)\n    File \"/Users/wtc/anaconda3/envs/tf-metal/lib/python3.10/site-packages/keras/src/losses.py\", line 142, in __call__\n        losses = call_fn(y_true, y_pred)\n    File \"/Users/wtc/anaconda3/envs/tf-metal/lib/python3.10/site-packages/keras/src/losses.py\", line 268, in call  **\n        return ag_fn(y_true, y_pred, **self._fn_kwargs)\n    File \"/Users/wtc/anaconda3/envs/tf-metal/lib/python3.10/site-packages/keras/src/losses.py\", line 2122, in categorical_crossentropy\n        return backend.categorical_crossentropy(\n    File \"/Users/wtc/anaconda3/envs/tf-metal/lib/python3.10/site-packages/keras/src/backend.py\", line 5560, in categorical_crossentropy\n        target.shape.assert_is_compatible_with(output.shape)\n\n    ValueError: Shapes (None, 8) and (None, 28, 28, 8) are incompatible\n\n\n--------------------------------------------------------------------------------\n1 fits failed with the following error:\nTraceback (most recent call last):\n  File \"/Users/wtc/anaconda3/envs/tf-metal/lib/python3.10/site-packages/sklearn/model_selection/_validation.py\", line 732, in _fit_and_score\n    estimator.fit(X_train, y_train, **fit_params)\n  File \"/Users/wtc/anaconda3/envs/tf-metal/lib/python3.10/site-packages/scikeras/wrappers.py\", line 1491, in fit\n    super().fit(X=X, y=y, sample_weight=sample_weight, **kwargs)\n  File \"/Users/wtc/anaconda3/envs/tf-metal/lib/python3.10/site-packages/scikeras/wrappers.py\", line 760, in fit\n    self._fit(\n  File \"/Users/wtc/anaconda3/envs/tf-metal/lib/python3.10/site-packages/scikeras/wrappers.py\", line 928, in _fit\n    self._fit_keras_model(\n  File \"/Users/wtc/anaconda3/envs/tf-metal/lib/python3.10/site-packages/scikeras/wrappers.py\", line 524, in _fit_keras_model\n    hist = self.model_.fit(x=X, y=y, **fit_args)\n  File \"/Users/wtc/anaconda3/envs/tf-metal/lib/python3.10/site-packages/keras/src/utils/traceback_utils.py\", line 70, in error_handler\n    raise e.with_traceback(filtered_tb) from None\n  File \"/var/folders/4w/p3jk6v8j135cv56t4gzkzv3r0000gn/T/__autograph_generated_file7tumjq1w.py\", line 15, in tf__train_function\n    retval_ = ag__.converted_call(ag__.ld(step_function), (ag__.ld(self), ag__.ld(iterator)), None, fscope)\nValueError: in user code:\n\n    File \"/Users/wtc/anaconda3/envs/tf-metal/lib/python3.10/site-packages/keras/src/engine/training.py\", line 1338, in train_function  *\n        return step_function(self, iterator)\n    File \"/Users/wtc/anaconda3/envs/tf-metal/lib/python3.10/site-packages/keras/src/engine/training.py\", line 1322, in step_function  **\n        outputs = model.distribute_strategy.run(run_step, args=(data,))\n    File \"/Users/wtc/anaconda3/envs/tf-metal/lib/python3.10/site-packages/keras/src/engine/training.py\", line 1303, in run_step  **\n        outputs = model.train_step(data)\n    File \"/Users/wtc/anaconda3/envs/tf-metal/lib/python3.10/site-packages/keras/src/engine/training.py\", line 1081, in train_step\n        loss = self.compute_loss(x, y, y_pred, sample_weight)\n    File \"/Users/wtc/anaconda3/envs/tf-metal/lib/python3.10/site-packages/keras/src/engine/training.py\", line 1139, in compute_loss\n        return self.compiled_loss(\n    File \"/Users/wtc/anaconda3/envs/tf-metal/lib/python3.10/site-packages/keras/src/engine/compile_utils.py\", line 265, in __call__\n        loss_value = loss_obj(y_t, y_p, sample_weight=sw)\n    File \"/Users/wtc/anaconda3/envs/tf-metal/lib/python3.10/site-packages/keras/src/losses.py\", line 142, in __call__\n        losses = call_fn(y_true, y_pred)\n    File \"/Users/wtc/anaconda3/envs/tf-metal/lib/python3.10/site-packages/keras/src/losses.py\", line 268, in call  **\n        return ag_fn(y_true, y_pred, **self._fn_kwargs)\n    File \"/Users/wtc/anaconda3/envs/tf-metal/lib/python3.10/site-packages/keras/src/losses.py\", line 2122, in categorical_crossentropy\n        return backend.categorical_crossentropy(\n    File \"/Users/wtc/anaconda3/envs/tf-metal/lib/python3.10/site-packages/keras/src/backend.py\", line 5560, in categorical_crossentropy\n        target.shape.assert_is_compatible_with(output.shape)\n\n    ValueError: Shapes (None, 8) and (None, 28, 28, 8) are incompatible\n\n\n--------------------------------------------------------------------------------\n2 fits failed with the following error:\nTraceback (most recent call last):\n  File \"/Users/wtc/anaconda3/envs/tf-metal/lib/python3.10/site-packages/sklearn/model_selection/_validation.py\", line 732, in _fit_and_score\n    estimator.fit(X_train, y_train, **fit_params)\n  File \"/Users/wtc/anaconda3/envs/tf-metal/lib/python3.10/site-packages/scikeras/wrappers.py\", line 1491, in fit\n    super().fit(X=X, y=y, sample_weight=sample_weight, **kwargs)\n  File \"/Users/wtc/anaconda3/envs/tf-metal/lib/python3.10/site-packages/scikeras/wrappers.py\", line 760, in fit\n    self._fit(\n  File \"/Users/wtc/anaconda3/envs/tf-metal/lib/python3.10/site-packages/scikeras/wrappers.py\", line 928, in _fit\n    self._fit_keras_model(\n  File \"/Users/wtc/anaconda3/envs/tf-metal/lib/python3.10/site-packages/scikeras/wrappers.py\", line 524, in _fit_keras_model\n    hist = self.model_.fit(x=X, y=y, **fit_args)\n  File \"/Users/wtc/anaconda3/envs/tf-metal/lib/python3.10/site-packages/keras/src/utils/traceback_utils.py\", line 70, in error_handler\n    raise e.with_traceback(filtered_tb) from None\n  File \"/var/folders/4w/p3jk6v8j135cv56t4gzkzv3r0000gn/T/__autograph_generated_fileskpy5br1.py\", line 15, in tf__train_function\n    retval_ = ag__.converted_call(ag__.ld(step_function), (ag__.ld(self), ag__.ld(iterator)), None, fscope)\nValueError: in user code:\n\n    File \"/Users/wtc/anaconda3/envs/tf-metal/lib/python3.10/site-packages/keras/src/engine/training.py\", line 1338, in train_function  *\n        return step_function(self, iterator)\n    File \"/Users/wtc/anaconda3/envs/tf-metal/lib/python3.10/site-packages/keras/src/engine/training.py\", line 1322, in step_function  **\n        outputs = model.distribute_strategy.run(run_step, args=(data,))\n    File \"/Users/wtc/anaconda3/envs/tf-metal/lib/python3.10/site-packages/keras/src/engine/training.py\", line 1303, in run_step  **\n        outputs = model.train_step(data)\n    File \"/Users/wtc/anaconda3/envs/tf-metal/lib/python3.10/site-packages/keras/src/engine/training.py\", line 1081, in train_step\n        loss = self.compute_loss(x, y, y_pred, sample_weight)\n    File \"/Users/wtc/anaconda3/envs/tf-metal/lib/python3.10/site-packages/keras/src/engine/training.py\", line 1139, in compute_loss\n        return self.compiled_loss(\n    File \"/Users/wtc/anaconda3/envs/tf-metal/lib/python3.10/site-packages/keras/src/engine/compile_utils.py\", line 265, in __call__\n        loss_value = loss_obj(y_t, y_p, sample_weight=sw)\n    File \"/Users/wtc/anaconda3/envs/tf-metal/lib/python3.10/site-packages/keras/src/losses.py\", line 142, in __call__\n        losses = call_fn(y_true, y_pred)\n    File \"/Users/wtc/anaconda3/envs/tf-metal/lib/python3.10/site-packages/keras/src/losses.py\", line 268, in call  **\n        return ag_fn(y_true, y_pred, **self._fn_kwargs)\n    File \"/Users/wtc/anaconda3/envs/tf-metal/lib/python3.10/site-packages/keras/src/losses.py\", line 2122, in categorical_crossentropy\n        return backend.categorical_crossentropy(\n    File \"/Users/wtc/anaconda3/envs/tf-metal/lib/python3.10/site-packages/keras/src/backend.py\", line 5560, in categorical_crossentropy\n        target.shape.assert_is_compatible_with(output.shape)\n\n    ValueError: Shapes (None, 8) and (None, 28, 28, 8) are incompatible\n\n\n--------------------------------------------------------------------------------\n1 fits failed with the following error:\nTraceback (most recent call last):\n  File \"/Users/wtc/anaconda3/envs/tf-metal/lib/python3.10/site-packages/sklearn/model_selection/_validation.py\", line 732, in _fit_and_score\n    estimator.fit(X_train, y_train, **fit_params)\n  File \"/Users/wtc/anaconda3/envs/tf-metal/lib/python3.10/site-packages/scikeras/wrappers.py\", line 1491, in fit\n    super().fit(X=X, y=y, sample_weight=sample_weight, **kwargs)\n  File \"/Users/wtc/anaconda3/envs/tf-metal/lib/python3.10/site-packages/scikeras/wrappers.py\", line 760, in fit\n    self._fit(\n  File \"/Users/wtc/anaconda3/envs/tf-metal/lib/python3.10/site-packages/scikeras/wrappers.py\", line 928, in _fit\n    self._fit_keras_model(\n  File \"/Users/wtc/anaconda3/envs/tf-metal/lib/python3.10/site-packages/scikeras/wrappers.py\", line 524, in _fit_keras_model\n    hist = self.model_.fit(x=X, y=y, **fit_args)\n  File \"/Users/wtc/anaconda3/envs/tf-metal/lib/python3.10/site-packages/keras/src/utils/traceback_utils.py\", line 70, in error_handler\n    raise e.with_traceback(filtered_tb) from None\n  File \"/var/folders/4w/p3jk6v8j135cv56t4gzkzv3r0000gn/T/__autograph_generated_filejxk2y29r.py\", line 15, in tf__train_function\n    retval_ = ag__.converted_call(ag__.ld(step_function), (ag__.ld(self), ag__.ld(iterator)), None, fscope)\nValueError: in user code:\n\n    File \"/Users/wtc/anaconda3/envs/tf-metal/lib/python3.10/site-packages/keras/src/engine/training.py\", line 1338, in train_function  *\n        return step_function(self, iterator)\n    File \"/Users/wtc/anaconda3/envs/tf-metal/lib/python3.10/site-packages/keras/src/engine/training.py\", line 1322, in step_function  **\n        outputs = model.distribute_strategy.run(run_step, args=(data,))\n    File \"/Users/wtc/anaconda3/envs/tf-metal/lib/python3.10/site-packages/keras/src/engine/training.py\", line 1303, in run_step  **\n        outputs = model.train_step(data)\n    File \"/Users/wtc/anaconda3/envs/tf-metal/lib/python3.10/site-packages/keras/src/engine/training.py\", line 1081, in train_step\n        loss = self.compute_loss(x, y, y_pred, sample_weight)\n    File \"/Users/wtc/anaconda3/envs/tf-metal/lib/python3.10/site-packages/keras/src/engine/training.py\", line 1139, in compute_loss\n        return self.compiled_loss(\n    File \"/Users/wtc/anaconda3/envs/tf-metal/lib/python3.10/site-packages/keras/src/engine/compile_utils.py\", line 265, in __call__\n        loss_value = loss_obj(y_t, y_p, sample_weight=sw)\n    File \"/Users/wtc/anaconda3/envs/tf-metal/lib/python3.10/site-packages/keras/src/losses.py\", line 142, in __call__\n        losses = call_fn(y_true, y_pred)\n    File \"/Users/wtc/anaconda3/envs/tf-metal/lib/python3.10/site-packages/keras/src/losses.py\", line 268, in call  **\n        return ag_fn(y_true, y_pred, **self._fn_kwargs)\n    File \"/Users/wtc/anaconda3/envs/tf-metal/lib/python3.10/site-packages/keras/src/losses.py\", line 2122, in categorical_crossentropy\n        return backend.categorical_crossentropy(\n    File \"/Users/wtc/anaconda3/envs/tf-metal/lib/python3.10/site-packages/keras/src/backend.py\", line 5560, in categorical_crossentropy\n        target.shape.assert_is_compatible_with(output.shape)\n\n    ValueError: Shapes (None, 8) and (None, 28, 28, 8) are incompatible\n\n",
     "output_type": "error",
     "traceback": [
      "\u001b[0;31m---------------------------------------------------------------------------\u001b[0m",
      "\u001b[0;31mValueError\u001b[0m                                Traceback (most recent call last)",
      "\u001b[1;32m/Users/wtc/Documents/USYD/COMP 5318/ASM2/5318ASM2/test.ipynb 单元格 13\u001b[0m line \u001b[0;36m2\n\u001b[1;32m     <a href='vscode-notebook-cell:/Users/wtc/Documents/USYD/COMP%205318/ASM2/5318ASM2/test.ipynb#X14sZmlsZQ%3D%3D?line=22'>23</a>\u001b[0m param_grid \u001b[39m=\u001b[39m \u001b[39mdict\u001b[39m(batch_size\u001b[39m=\u001b[39mbatch_size, epochs\u001b[39m=\u001b[39mepochs)\n\u001b[1;32m     <a href='vscode-notebook-cell:/Users/wtc/Documents/USYD/COMP%205318/ASM2/5318ASM2/test.ipynb#X14sZmlsZQ%3D%3D?line=23'>24</a>\u001b[0m grid \u001b[39m=\u001b[39m GridSearchCV(estimator\u001b[39m=\u001b[39mmodel, param_grid\u001b[39m=\u001b[39mparam_grid, n_jobs\u001b[39m=\u001b[39m\u001b[39m-\u001b[39m\u001b[39m1\u001b[39m, cv\u001b[39m=\u001b[39m\u001b[39m3\u001b[39m)\n\u001b[0;32m---> <a href='vscode-notebook-cell:/Users/wtc/Documents/USYD/COMP%205318/ASM2/5318ASM2/test.ipynb#X14sZmlsZQ%3D%3D?line=24'>25</a>\u001b[0m grid_result \u001b[39m=\u001b[39m grid\u001b[39m.\u001b[39;49mfit(X_train_n, y_train_c)\n\u001b[1;32m     <a href='vscode-notebook-cell:/Users/wtc/Documents/USYD/COMP%205318/ASM2/5318ASM2/test.ipynb#X14sZmlsZQ%3D%3D?line=25'>26</a>\u001b[0m \u001b[39m# summarize results\u001b[39;00m\n\u001b[1;32m     <a href='vscode-notebook-cell:/Users/wtc/Documents/USYD/COMP%205318/ASM2/5318ASM2/test.ipynb#X14sZmlsZQ%3D%3D?line=26'>27</a>\u001b[0m \u001b[39mprint\u001b[39m(\u001b[39m\"\u001b[39m\u001b[39mBest: \u001b[39m\u001b[39m%f\u001b[39;00m\u001b[39m using \u001b[39m\u001b[39m%s\u001b[39;00m\u001b[39m\"\u001b[39m \u001b[39m%\u001b[39m (grid_result\u001b[39m.\u001b[39mbest_score_, grid_result\u001b[39m.\u001b[39mbest_params_))\n",
      "File \u001b[0;32m~/anaconda3/envs/tf-metal/lib/python3.10/site-packages/sklearn/base.py:1151\u001b[0m, in \u001b[0;36m_fit_context.<locals>.decorator.<locals>.wrapper\u001b[0;34m(estimator, *args, **kwargs)\u001b[0m\n\u001b[1;32m   1144\u001b[0m     estimator\u001b[39m.\u001b[39m_validate_params()\n\u001b[1;32m   1146\u001b[0m \u001b[39mwith\u001b[39;00m config_context(\n\u001b[1;32m   1147\u001b[0m     skip_parameter_validation\u001b[39m=\u001b[39m(\n\u001b[1;32m   1148\u001b[0m         prefer_skip_nested_validation \u001b[39mor\u001b[39;00m global_skip_validation\n\u001b[1;32m   1149\u001b[0m     )\n\u001b[1;32m   1150\u001b[0m ):\n\u001b[0;32m-> 1151\u001b[0m     \u001b[39mreturn\u001b[39;00m fit_method(estimator, \u001b[39m*\u001b[39;49margs, \u001b[39m*\u001b[39;49m\u001b[39m*\u001b[39;49mkwargs)\n",
      "File \u001b[0;32m~/anaconda3/envs/tf-metal/lib/python3.10/site-packages/sklearn/model_selection/_search.py:898\u001b[0m, in \u001b[0;36mBaseSearchCV.fit\u001b[0;34m(self, X, y, groups, **fit_params)\u001b[0m\n\u001b[1;32m    892\u001b[0m     results \u001b[39m=\u001b[39m \u001b[39mself\u001b[39m\u001b[39m.\u001b[39m_format_results(\n\u001b[1;32m    893\u001b[0m         all_candidate_params, n_splits, all_out, all_more_results\n\u001b[1;32m    894\u001b[0m     )\n\u001b[1;32m    896\u001b[0m     \u001b[39mreturn\u001b[39;00m results\n\u001b[0;32m--> 898\u001b[0m \u001b[39mself\u001b[39;49m\u001b[39m.\u001b[39;49m_run_search(evaluate_candidates)\n\u001b[1;32m    900\u001b[0m \u001b[39m# multimetric is determined here because in the case of a callable\u001b[39;00m\n\u001b[1;32m    901\u001b[0m \u001b[39m# self.scoring the return type is only known after calling\u001b[39;00m\n\u001b[1;32m    902\u001b[0m first_test_score \u001b[39m=\u001b[39m all_out[\u001b[39m0\u001b[39m][\u001b[39m\"\u001b[39m\u001b[39mtest_scores\u001b[39m\u001b[39m\"\u001b[39m]\n",
      "File \u001b[0;32m~/anaconda3/envs/tf-metal/lib/python3.10/site-packages/sklearn/model_selection/_search.py:1419\u001b[0m, in \u001b[0;36mGridSearchCV._run_search\u001b[0;34m(self, evaluate_candidates)\u001b[0m\n\u001b[1;32m   1417\u001b[0m \u001b[39mdef\u001b[39;00m \u001b[39m_run_search\u001b[39m(\u001b[39mself\u001b[39m, evaluate_candidates):\n\u001b[1;32m   1418\u001b[0m \u001b[39m    \u001b[39m\u001b[39m\"\"\"Search all candidates in param_grid\"\"\"\u001b[39;00m\n\u001b[0;32m-> 1419\u001b[0m     evaluate_candidates(ParameterGrid(\u001b[39mself\u001b[39;49m\u001b[39m.\u001b[39;49mparam_grid))\n",
      "File \u001b[0;32m~/anaconda3/envs/tf-metal/lib/python3.10/site-packages/sklearn/model_selection/_search.py:875\u001b[0m, in \u001b[0;36mBaseSearchCV.fit.<locals>.evaluate_candidates\u001b[0;34m(candidate_params, cv, more_results)\u001b[0m\n\u001b[1;32m    868\u001b[0m \u001b[39melif\u001b[39;00m \u001b[39mlen\u001b[39m(out) \u001b[39m!=\u001b[39m n_candidates \u001b[39m*\u001b[39m n_splits:\n\u001b[1;32m    869\u001b[0m     \u001b[39mraise\u001b[39;00m \u001b[39mValueError\u001b[39;00m(\n\u001b[1;32m    870\u001b[0m         \u001b[39m\"\u001b[39m\u001b[39mcv.split and cv.get_n_splits returned \u001b[39m\u001b[39m\"\u001b[39m\n\u001b[1;32m    871\u001b[0m         \u001b[39m\"\u001b[39m\u001b[39minconsistent results. Expected \u001b[39m\u001b[39m{}\u001b[39;00m\u001b[39m \u001b[39m\u001b[39m\"\u001b[39m\n\u001b[1;32m    872\u001b[0m         \u001b[39m\"\u001b[39m\u001b[39msplits, got \u001b[39m\u001b[39m{}\u001b[39;00m\u001b[39m\"\u001b[39m\u001b[39m.\u001b[39mformat(n_splits, \u001b[39mlen\u001b[39m(out) \u001b[39m/\u001b[39m\u001b[39m/\u001b[39m n_candidates)\n\u001b[1;32m    873\u001b[0m     )\n\u001b[0;32m--> 875\u001b[0m _warn_or_raise_about_fit_failures(out, \u001b[39mself\u001b[39;49m\u001b[39m.\u001b[39;49merror_score)\n\u001b[1;32m    877\u001b[0m \u001b[39m# For callable self.scoring, the return type is only know after\u001b[39;00m\n\u001b[1;32m    878\u001b[0m \u001b[39m# calling. If the return type is a dictionary, the error scores\u001b[39;00m\n\u001b[1;32m    879\u001b[0m \u001b[39m# can now be inserted with the correct key. The type checking\u001b[39;00m\n\u001b[1;32m    880\u001b[0m \u001b[39m# of out will be done in `_insert_error_scores`.\u001b[39;00m\n\u001b[1;32m    881\u001b[0m \u001b[39mif\u001b[39;00m \u001b[39mcallable\u001b[39m(\u001b[39mself\u001b[39m\u001b[39m.\u001b[39mscoring):\n",
      "File \u001b[0;32m~/anaconda3/envs/tf-metal/lib/python3.10/site-packages/sklearn/model_selection/_validation.py:414\u001b[0m, in \u001b[0;36m_warn_or_raise_about_fit_failures\u001b[0;34m(results, error_score)\u001b[0m\n\u001b[1;32m    407\u001b[0m \u001b[39mif\u001b[39;00m num_failed_fits \u001b[39m==\u001b[39m num_fits:\n\u001b[1;32m    408\u001b[0m     all_fits_failed_message \u001b[39m=\u001b[39m (\n\u001b[1;32m    409\u001b[0m         \u001b[39mf\u001b[39m\u001b[39m\"\u001b[39m\u001b[39m\\n\u001b[39;00m\u001b[39mAll the \u001b[39m\u001b[39m{\u001b[39;00mnum_fits\u001b[39m}\u001b[39;00m\u001b[39m fits failed.\u001b[39m\u001b[39m\\n\u001b[39;00m\u001b[39m\"\u001b[39m\n\u001b[1;32m    410\u001b[0m         \u001b[39m\"\u001b[39m\u001b[39mIt is very likely that your model is misconfigured.\u001b[39m\u001b[39m\\n\u001b[39;00m\u001b[39m\"\u001b[39m\n\u001b[1;32m    411\u001b[0m         \u001b[39m\"\u001b[39m\u001b[39mYou can try to debug the error by setting error_score=\u001b[39m\u001b[39m'\u001b[39m\u001b[39mraise\u001b[39m\u001b[39m'\u001b[39m\u001b[39m.\u001b[39m\u001b[39m\\n\u001b[39;00m\u001b[39m\\n\u001b[39;00m\u001b[39m\"\u001b[39m\n\u001b[1;32m    412\u001b[0m         \u001b[39mf\u001b[39m\u001b[39m\"\u001b[39m\u001b[39mBelow are more details about the failures:\u001b[39m\u001b[39m\\n\u001b[39;00m\u001b[39m{\u001b[39;00mfit_errors_summary\u001b[39m}\u001b[39;00m\u001b[39m\"\u001b[39m\n\u001b[1;32m    413\u001b[0m     )\n\u001b[0;32m--> 414\u001b[0m     \u001b[39mraise\u001b[39;00m \u001b[39mValueError\u001b[39;00m(all_fits_failed_message)\n\u001b[1;32m    416\u001b[0m \u001b[39melse\u001b[39;00m:\n\u001b[1;32m    417\u001b[0m     some_fits_failed_message \u001b[39m=\u001b[39m (\n\u001b[1;32m    418\u001b[0m         \u001b[39mf\u001b[39m\u001b[39m\"\u001b[39m\u001b[39m\\n\u001b[39;00m\u001b[39m{\u001b[39;00mnum_failed_fits\u001b[39m}\u001b[39;00m\u001b[39m fits failed out of a total of \u001b[39m\u001b[39m{\u001b[39;00mnum_fits\u001b[39m}\u001b[39;00m\u001b[39m.\u001b[39m\u001b[39m\\n\u001b[39;00m\u001b[39m\"\u001b[39m\n\u001b[1;32m    419\u001b[0m         \u001b[39m\"\u001b[39m\u001b[39mThe score on these train-test partitions for these parameters\u001b[39m\u001b[39m\"\u001b[39m\n\u001b[0;32m   (...)\u001b[0m\n\u001b[1;32m    423\u001b[0m         \u001b[39mf\u001b[39m\u001b[39m\"\u001b[39m\u001b[39mBelow are more details about the failures:\u001b[39m\u001b[39m\\n\u001b[39;00m\u001b[39m{\u001b[39;00mfit_errors_summary\u001b[39m}\u001b[39;00m\u001b[39m\"\u001b[39m\n\u001b[1;32m    424\u001b[0m     )\n",
      "\u001b[0;31mValueError\u001b[0m: \nAll the 12 fits failed.\nIt is very likely that your model is misconfigured.\nYou can try to debug the error by setting error_score='raise'.\n\nBelow are more details about the failures:\n--------------------------------------------------------------------------------\n2 fits failed with the following error:\nTraceback (most recent call last):\n  File \"/Users/wtc/anaconda3/envs/tf-metal/lib/python3.10/site-packages/sklearn/model_selection/_validation.py\", line 732, in _fit_and_score\n    estimator.fit(X_train, y_train, **fit_params)\n  File \"/Users/wtc/anaconda3/envs/tf-metal/lib/python3.10/site-packages/scikeras/wrappers.py\", line 1491, in fit\n    super().fit(X=X, y=y, sample_weight=sample_weight, **kwargs)\n  File \"/Users/wtc/anaconda3/envs/tf-metal/lib/python3.10/site-packages/scikeras/wrappers.py\", line 760, in fit\n    self._fit(\n  File \"/Users/wtc/anaconda3/envs/tf-metal/lib/python3.10/site-packages/scikeras/wrappers.py\", line 928, in _fit\n    self._fit_keras_model(\n  File \"/Users/wtc/anaconda3/envs/tf-metal/lib/python3.10/site-packages/scikeras/wrappers.py\", line 524, in _fit_keras_model\n    hist = self.model_.fit(x=X, y=y, **fit_args)\n  File \"/Users/wtc/anaconda3/envs/tf-metal/lib/python3.10/site-packages/keras/src/utils/traceback_utils.py\", line 70, in error_handler\n    raise e.with_traceback(filtered_tb) from None\n  File \"/var/folders/4w/p3jk6v8j135cv56t4gzkzv3r0000gn/T/__autograph_generated_filemf5ei3g5.py\", line 15, in tf__train_function\n    retval_ = ag__.converted_call(ag__.ld(step_function), (ag__.ld(self), ag__.ld(iterator)), None, fscope)\nValueError: in user code:\n\n    File \"/Users/wtc/anaconda3/envs/tf-metal/lib/python3.10/site-packages/keras/src/engine/training.py\", line 1338, in train_function  *\n        return step_function(self, iterator)\n    File \"/Users/wtc/anaconda3/envs/tf-metal/lib/python3.10/site-packages/keras/src/engine/training.py\", line 1322, in step_function  **\n        outputs = model.distribute_strategy.run(run_step, args=(data,))\n    File \"/Users/wtc/anaconda3/envs/tf-metal/lib/python3.10/site-packages/keras/src/engine/training.py\", line 1303, in run_step  **\n        outputs = model.train_step(data)\n    File \"/Users/wtc/anaconda3/envs/tf-metal/lib/python3.10/site-packages/keras/src/engine/training.py\", line 1081, in train_step\n        loss = self.compute_loss(x, y, y_pred, sample_weight)\n    File \"/Users/wtc/anaconda3/envs/tf-metal/lib/python3.10/site-packages/keras/src/engine/training.py\", line 1139, in compute_loss\n        return self.compiled_loss(\n    File \"/Users/wtc/anaconda3/envs/tf-metal/lib/python3.10/site-packages/keras/src/engine/compile_utils.py\", line 265, in __call__\n        loss_value = loss_obj(y_t, y_p, sample_weight=sw)\n    File \"/Users/wtc/anaconda3/envs/tf-metal/lib/python3.10/site-packages/keras/src/losses.py\", line 142, in __call__\n        losses = call_fn(y_true, y_pred)\n    File \"/Users/wtc/anaconda3/envs/tf-metal/lib/python3.10/site-packages/keras/src/losses.py\", line 268, in call  **\n        return ag_fn(y_true, y_pred, **self._fn_kwargs)\n    File \"/Users/wtc/anaconda3/envs/tf-metal/lib/python3.10/site-packages/keras/src/losses.py\", line 2122, in categorical_crossentropy\n        return backend.categorical_crossentropy(\n    File \"/Users/wtc/anaconda3/envs/tf-metal/lib/python3.10/site-packages/keras/src/backend.py\", line 5560, in categorical_crossentropy\n        target.shape.assert_is_compatible_with(output.shape)\n\n    ValueError: Shapes (None, 8) and (None, 28, 28, 8) are incompatible\n\n\n--------------------------------------------------------------------------------\n1 fits failed with the following error:\nTraceback (most recent call last):\n  File \"/Users/wtc/anaconda3/envs/tf-metal/lib/python3.10/site-packages/sklearn/model_selection/_validation.py\", line 732, in _fit_and_score\n    estimator.fit(X_train, y_train, **fit_params)\n  File \"/Users/wtc/anaconda3/envs/tf-metal/lib/python3.10/site-packages/scikeras/wrappers.py\", line 1491, in fit\n    super().fit(X=X, y=y, sample_weight=sample_weight, **kwargs)\n  File \"/Users/wtc/anaconda3/envs/tf-metal/lib/python3.10/site-packages/scikeras/wrappers.py\", line 760, in fit\n    self._fit(\n  File \"/Users/wtc/anaconda3/envs/tf-metal/lib/python3.10/site-packages/scikeras/wrappers.py\", line 928, in _fit\n    self._fit_keras_model(\n  File \"/Users/wtc/anaconda3/envs/tf-metal/lib/python3.10/site-packages/scikeras/wrappers.py\", line 524, in _fit_keras_model\n    hist = self.model_.fit(x=X, y=y, **fit_args)\n  File \"/Users/wtc/anaconda3/envs/tf-metal/lib/python3.10/site-packages/keras/src/utils/traceback_utils.py\", line 70, in error_handler\n    raise e.with_traceback(filtered_tb) from None\n  File \"/var/folders/4w/p3jk6v8j135cv56t4gzkzv3r0000gn/T/__autograph_generated_filee168y96t.py\", line 15, in tf__train_function\n    retval_ = ag__.converted_call(ag__.ld(step_function), (ag__.ld(self), ag__.ld(iterator)), None, fscope)\nValueError: in user code:\n\n    File \"/Users/wtc/anaconda3/envs/tf-metal/lib/python3.10/site-packages/keras/src/engine/training.py\", line 1338, in train_function  *\n        return step_function(self, iterator)\n    File \"/Users/wtc/anaconda3/envs/tf-metal/lib/python3.10/site-packages/keras/src/engine/training.py\", line 1322, in step_function  **\n        outputs = model.distribute_strategy.run(run_step, args=(data,))\n    File \"/Users/wtc/anaconda3/envs/tf-metal/lib/python3.10/site-packages/keras/src/engine/training.py\", line 1303, in run_step  **\n        outputs = model.train_step(data)\n    File \"/Users/wtc/anaconda3/envs/tf-metal/lib/python3.10/site-packages/keras/src/engine/training.py\", line 1081, in train_step\n        loss = self.compute_loss(x, y, y_pred, sample_weight)\n    File \"/Users/wtc/anaconda3/envs/tf-metal/lib/python3.10/site-packages/keras/src/engine/training.py\", line 1139, in compute_loss\n        return self.compiled_loss(\n    File \"/Users/wtc/anaconda3/envs/tf-metal/lib/python3.10/site-packages/keras/src/engine/compile_utils.py\", line 265, in __call__\n        loss_value = loss_obj(y_t, y_p, sample_weight=sw)\n    File \"/Users/wtc/anaconda3/envs/tf-metal/lib/python3.10/site-packages/keras/src/losses.py\", line 142, in __call__\n        losses = call_fn(y_true, y_pred)\n    File \"/Users/wtc/anaconda3/envs/tf-metal/lib/python3.10/site-packages/keras/src/losses.py\", line 268, in call  **\n        return ag_fn(y_true, y_pred, **self._fn_kwargs)\n    File \"/Users/wtc/anaconda3/envs/tf-metal/lib/python3.10/site-packages/keras/src/losses.py\", line 2122, in categorical_crossentropy\n        return backend.categorical_crossentropy(\n    File \"/Users/wtc/anaconda3/envs/tf-metal/lib/python3.10/site-packages/keras/src/backend.py\", line 5560, in categorical_crossentropy\n        target.shape.assert_is_compatible_with(output.shape)\n\n    ValueError: Shapes (None, 8) and (None, 28, 28, 8) are incompatible\n\n\n--------------------------------------------------------------------------------\n2 fits failed with the following error:\nTraceback (most recent call last):\n  File \"/Users/wtc/anaconda3/envs/tf-metal/lib/python3.10/site-packages/sklearn/model_selection/_validation.py\", line 732, in _fit_and_score\n    estimator.fit(X_train, y_train, **fit_params)\n  File \"/Users/wtc/anaconda3/envs/tf-metal/lib/python3.10/site-packages/scikeras/wrappers.py\", line 1491, in fit\n    super().fit(X=X, y=y, sample_weight=sample_weight, **kwargs)\n  File \"/Users/wtc/anaconda3/envs/tf-metal/lib/python3.10/site-packages/scikeras/wrappers.py\", line 760, in fit\n    self._fit(\n  File \"/Users/wtc/anaconda3/envs/tf-metal/lib/python3.10/site-packages/scikeras/wrappers.py\", line 928, in _fit\n    self._fit_keras_model(\n  File \"/Users/wtc/anaconda3/envs/tf-metal/lib/python3.10/site-packages/scikeras/wrappers.py\", line 524, in _fit_keras_model\n    hist = self.model_.fit(x=X, y=y, **fit_args)\n  File \"/Users/wtc/anaconda3/envs/tf-metal/lib/python3.10/site-packages/keras/src/utils/traceback_utils.py\", line 70, in error_handler\n    raise e.with_traceback(filtered_tb) from None\n  File \"/var/folders/4w/p3jk6v8j135cv56t4gzkzv3r0000gn/T/__autograph_generated_fileuncpeb_n.py\", line 15, in tf__train_function\n    retval_ = ag__.converted_call(ag__.ld(step_function), (ag__.ld(self), ag__.ld(iterator)), None, fscope)\nValueError: in user code:\n\n    File \"/Users/wtc/anaconda3/envs/tf-metal/lib/python3.10/site-packages/keras/src/engine/training.py\", line 1338, in train_function  *\n        return step_function(self, iterator)\n    File \"/Users/wtc/anaconda3/envs/tf-metal/lib/python3.10/site-packages/keras/src/engine/training.py\", line 1322, in step_function  **\n        outputs = model.distribute_strategy.run(run_step, args=(data,))\n    File \"/Users/wtc/anaconda3/envs/tf-metal/lib/python3.10/site-packages/keras/src/engine/training.py\", line 1303, in run_step  **\n        outputs = model.train_step(data)\n    File \"/Users/wtc/anaconda3/envs/tf-metal/lib/python3.10/site-packages/keras/src/engine/training.py\", line 1081, in train_step\n        loss = self.compute_loss(x, y, y_pred, sample_weight)\n    File \"/Users/wtc/anaconda3/envs/tf-metal/lib/python3.10/site-packages/keras/src/engine/training.py\", line 1139, in compute_loss\n        return self.compiled_loss(\n    File \"/Users/wtc/anaconda3/envs/tf-metal/lib/python3.10/site-packages/keras/src/engine/compile_utils.py\", line 265, in __call__\n        loss_value = loss_obj(y_t, y_p, sample_weight=sw)\n    File \"/Users/wtc/anaconda3/envs/tf-metal/lib/python3.10/site-packages/keras/src/losses.py\", line 142, in __call__\n        losses = call_fn(y_true, y_pred)\n    File \"/Users/wtc/anaconda3/envs/tf-metal/lib/python3.10/site-packages/keras/src/losses.py\", line 268, in call  **\n        return ag_fn(y_true, y_pred, **self._fn_kwargs)\n    File \"/Users/wtc/anaconda3/envs/tf-metal/lib/python3.10/site-packages/keras/src/losses.py\", line 2122, in categorical_crossentropy\n        return backend.categorical_crossentropy(\n    File \"/Users/wtc/anaconda3/envs/tf-metal/lib/python3.10/site-packages/keras/src/backend.py\", line 5560, in categorical_crossentropy\n        target.shape.assert_is_compatible_with(output.shape)\n\n    ValueError: Shapes (None, 8) and (None, 28, 28, 8) are incompatible\n\n\n--------------------------------------------------------------------------------\n1 fits failed with the following error:\nTraceback (most recent call last):\n  File \"/Users/wtc/anaconda3/envs/tf-metal/lib/python3.10/site-packages/sklearn/model_selection/_validation.py\", line 732, in _fit_and_score\n    estimator.fit(X_train, y_train, **fit_params)\n  File \"/Users/wtc/anaconda3/envs/tf-metal/lib/python3.10/site-packages/scikeras/wrappers.py\", line 1491, in fit\n    super().fit(X=X, y=y, sample_weight=sample_weight, **kwargs)\n  File \"/Users/wtc/anaconda3/envs/tf-metal/lib/python3.10/site-packages/scikeras/wrappers.py\", line 760, in fit\n    self._fit(\n  File \"/Users/wtc/anaconda3/envs/tf-metal/lib/python3.10/site-packages/scikeras/wrappers.py\", line 928, in _fit\n    self._fit_keras_model(\n  File \"/Users/wtc/anaconda3/envs/tf-metal/lib/python3.10/site-packages/scikeras/wrappers.py\", line 524, in _fit_keras_model\n    hist = self.model_.fit(x=X, y=y, **fit_args)\n  File \"/Users/wtc/anaconda3/envs/tf-metal/lib/python3.10/site-packages/keras/src/utils/traceback_utils.py\", line 70, in error_handler\n    raise e.with_traceback(filtered_tb) from None\n  File \"/var/folders/4w/p3jk6v8j135cv56t4gzkzv3r0000gn/T/__autograph_generated_fileuq0c4ggh.py\", line 15, in tf__train_function\n    retval_ = ag__.converted_call(ag__.ld(step_function), (ag__.ld(self), ag__.ld(iterator)), None, fscope)\nValueError: in user code:\n\n    File \"/Users/wtc/anaconda3/envs/tf-metal/lib/python3.10/site-packages/keras/src/engine/training.py\", line 1338, in train_function  *\n        return step_function(self, iterator)\n    File \"/Users/wtc/anaconda3/envs/tf-metal/lib/python3.10/site-packages/keras/src/engine/training.py\", line 1322, in step_function  **\n        outputs = model.distribute_strategy.run(run_step, args=(data,))\n    File \"/Users/wtc/anaconda3/envs/tf-metal/lib/python3.10/site-packages/keras/src/engine/training.py\", line 1303, in run_step  **\n        outputs = model.train_step(data)\n    File \"/Users/wtc/anaconda3/envs/tf-metal/lib/python3.10/site-packages/keras/src/engine/training.py\", line 1081, in train_step\n        loss = self.compute_loss(x, y, y_pred, sample_weight)\n    File \"/Users/wtc/anaconda3/envs/tf-metal/lib/python3.10/site-packages/keras/src/engine/training.py\", line 1139, in compute_loss\n        return self.compiled_loss(\n    File \"/Users/wtc/anaconda3/envs/tf-metal/lib/python3.10/site-packages/keras/src/engine/compile_utils.py\", line 265, in __call__\n        loss_value = loss_obj(y_t, y_p, sample_weight=sw)\n    File \"/Users/wtc/anaconda3/envs/tf-metal/lib/python3.10/site-packages/keras/src/losses.py\", line 142, in __call__\n        losses = call_fn(y_true, y_pred)\n    File \"/Users/wtc/anaconda3/envs/tf-metal/lib/python3.10/site-packages/keras/src/losses.py\", line 268, in call  **\n        return ag_fn(y_true, y_pred, **self._fn_kwargs)\n    File \"/Users/wtc/anaconda3/envs/tf-metal/lib/python3.10/site-packages/keras/src/losses.py\", line 2122, in categorical_crossentropy\n        return backend.categorical_crossentropy(\n    File \"/Users/wtc/anaconda3/envs/tf-metal/lib/python3.10/site-packages/keras/src/backend.py\", line 5560, in categorical_crossentropy\n        target.shape.assert_is_compatible_with(output.shape)\n\n    ValueError: Shapes (None, 8) and (None, 28, 28, 8) are incompatible\n\n\n--------------------------------------------------------------------------------\n2 fits failed with the following error:\nTraceback (most recent call last):\n  File \"/Users/wtc/anaconda3/envs/tf-metal/lib/python3.10/site-packages/sklearn/model_selection/_validation.py\", line 732, in _fit_and_score\n    estimator.fit(X_train, y_train, **fit_params)\n  File \"/Users/wtc/anaconda3/envs/tf-metal/lib/python3.10/site-packages/scikeras/wrappers.py\", line 1491, in fit\n    super().fit(X=X, y=y, sample_weight=sample_weight, **kwargs)\n  File \"/Users/wtc/anaconda3/envs/tf-metal/lib/python3.10/site-packages/scikeras/wrappers.py\", line 760, in fit\n    self._fit(\n  File \"/Users/wtc/anaconda3/envs/tf-metal/lib/python3.10/site-packages/scikeras/wrappers.py\", line 928, in _fit\n    self._fit_keras_model(\n  File \"/Users/wtc/anaconda3/envs/tf-metal/lib/python3.10/site-packages/scikeras/wrappers.py\", line 524, in _fit_keras_model\n    hist = self.model_.fit(x=X, y=y, **fit_args)\n  File \"/Users/wtc/anaconda3/envs/tf-metal/lib/python3.10/site-packages/keras/src/utils/traceback_utils.py\", line 70, in error_handler\n    raise e.with_traceback(filtered_tb) from None\n  File \"/var/folders/4w/p3jk6v8j135cv56t4gzkzv3r0000gn/T/__autograph_generated_filei1ufkfiy.py\", line 15, in tf__train_function\n    retval_ = ag__.converted_call(ag__.ld(step_function), (ag__.ld(self), ag__.ld(iterator)), None, fscope)\nValueError: in user code:\n\n    File \"/Users/wtc/anaconda3/envs/tf-metal/lib/python3.10/site-packages/keras/src/engine/training.py\", line 1338, in train_function  *\n        return step_function(self, iterator)\n    File \"/Users/wtc/anaconda3/envs/tf-metal/lib/python3.10/site-packages/keras/src/engine/training.py\", line 1322, in step_function  **\n        outputs = model.distribute_strategy.run(run_step, args=(data,))\n    File \"/Users/wtc/anaconda3/envs/tf-metal/lib/python3.10/site-packages/keras/src/engine/training.py\", line 1303, in run_step  **\n        outputs = model.train_step(data)\n    File \"/Users/wtc/anaconda3/envs/tf-metal/lib/python3.10/site-packages/keras/src/engine/training.py\", line 1081, in train_step\n        loss = self.compute_loss(x, y, y_pred, sample_weight)\n    File \"/Users/wtc/anaconda3/envs/tf-metal/lib/python3.10/site-packages/keras/src/engine/training.py\", line 1139, in compute_loss\n        return self.compiled_loss(\n    File \"/Users/wtc/anaconda3/envs/tf-metal/lib/python3.10/site-packages/keras/src/engine/compile_utils.py\", line 265, in __call__\n        loss_value = loss_obj(y_t, y_p, sample_weight=sw)\n    File \"/Users/wtc/anaconda3/envs/tf-metal/lib/python3.10/site-packages/keras/src/losses.py\", line 142, in __call__\n        losses = call_fn(y_true, y_pred)\n    File \"/Users/wtc/anaconda3/envs/tf-metal/lib/python3.10/site-packages/keras/src/losses.py\", line 268, in call  **\n        return ag_fn(y_true, y_pred, **self._fn_kwargs)\n    File \"/Users/wtc/anaconda3/envs/tf-metal/lib/python3.10/site-packages/keras/src/losses.py\", line 2122, in categorical_crossentropy\n        return backend.categorical_crossentropy(\n    File \"/Users/wtc/anaconda3/envs/tf-metal/lib/python3.10/site-packages/keras/src/backend.py\", line 5560, in categorical_crossentropy\n        target.shape.assert_is_compatible_with(output.shape)\n\n    ValueError: Shapes (None, 8) and (None, 28, 28, 8) are incompatible\n\n\n--------------------------------------------------------------------------------\n1 fits failed with the following error:\nTraceback (most recent call last):\n  File \"/Users/wtc/anaconda3/envs/tf-metal/lib/python3.10/site-packages/sklearn/model_selection/_validation.py\", line 732, in _fit_and_score\n    estimator.fit(X_train, y_train, **fit_params)\n  File \"/Users/wtc/anaconda3/envs/tf-metal/lib/python3.10/site-packages/scikeras/wrappers.py\", line 1491, in fit\n    super().fit(X=X, y=y, sample_weight=sample_weight, **kwargs)\n  File \"/Users/wtc/anaconda3/envs/tf-metal/lib/python3.10/site-packages/scikeras/wrappers.py\", line 760, in fit\n    self._fit(\n  File \"/Users/wtc/anaconda3/envs/tf-metal/lib/python3.10/site-packages/scikeras/wrappers.py\", line 928, in _fit\n    self._fit_keras_model(\n  File \"/Users/wtc/anaconda3/envs/tf-metal/lib/python3.10/site-packages/scikeras/wrappers.py\", line 524, in _fit_keras_model\n    hist = self.model_.fit(x=X, y=y, **fit_args)\n  File \"/Users/wtc/anaconda3/envs/tf-metal/lib/python3.10/site-packages/keras/src/utils/traceback_utils.py\", line 70, in error_handler\n    raise e.with_traceback(filtered_tb) from None\n  File \"/var/folders/4w/p3jk6v8j135cv56t4gzkzv3r0000gn/T/__autograph_generated_file7tumjq1w.py\", line 15, in tf__train_function\n    retval_ = ag__.converted_call(ag__.ld(step_function), (ag__.ld(self), ag__.ld(iterator)), None, fscope)\nValueError: in user code:\n\n    File \"/Users/wtc/anaconda3/envs/tf-metal/lib/python3.10/site-packages/keras/src/engine/training.py\", line 1338, in train_function  *\n        return step_function(self, iterator)\n    File \"/Users/wtc/anaconda3/envs/tf-metal/lib/python3.10/site-packages/keras/src/engine/training.py\", line 1322, in step_function  **\n        outputs = model.distribute_strategy.run(run_step, args=(data,))\n    File \"/Users/wtc/anaconda3/envs/tf-metal/lib/python3.10/site-packages/keras/src/engine/training.py\", line 1303, in run_step  **\n        outputs = model.train_step(data)\n    File \"/Users/wtc/anaconda3/envs/tf-metal/lib/python3.10/site-packages/keras/src/engine/training.py\", line 1081, in train_step\n        loss = self.compute_loss(x, y, y_pred, sample_weight)\n    File \"/Users/wtc/anaconda3/envs/tf-metal/lib/python3.10/site-packages/keras/src/engine/training.py\", line 1139, in compute_loss\n        return self.compiled_loss(\n    File \"/Users/wtc/anaconda3/envs/tf-metal/lib/python3.10/site-packages/keras/src/engine/compile_utils.py\", line 265, in __call__\n        loss_value = loss_obj(y_t, y_p, sample_weight=sw)\n    File \"/Users/wtc/anaconda3/envs/tf-metal/lib/python3.10/site-packages/keras/src/losses.py\", line 142, in __call__\n        losses = call_fn(y_true, y_pred)\n    File \"/Users/wtc/anaconda3/envs/tf-metal/lib/python3.10/site-packages/keras/src/losses.py\", line 268, in call  **\n        return ag_fn(y_true, y_pred, **self._fn_kwargs)\n    File \"/Users/wtc/anaconda3/envs/tf-metal/lib/python3.10/site-packages/keras/src/losses.py\", line 2122, in categorical_crossentropy\n        return backend.categorical_crossentropy(\n    File \"/Users/wtc/anaconda3/envs/tf-metal/lib/python3.10/site-packages/keras/src/backend.py\", line 5560, in categorical_crossentropy\n        target.shape.assert_is_compatible_with(output.shape)\n\n    ValueError: Shapes (None, 8) and (None, 28, 28, 8) are incompatible\n\n\n--------------------------------------------------------------------------------\n2 fits failed with the following error:\nTraceback (most recent call last):\n  File \"/Users/wtc/anaconda3/envs/tf-metal/lib/python3.10/site-packages/sklearn/model_selection/_validation.py\", line 732, in _fit_and_score\n    estimator.fit(X_train, y_train, **fit_params)\n  File \"/Users/wtc/anaconda3/envs/tf-metal/lib/python3.10/site-packages/scikeras/wrappers.py\", line 1491, in fit\n    super().fit(X=X, y=y, sample_weight=sample_weight, **kwargs)\n  File \"/Users/wtc/anaconda3/envs/tf-metal/lib/python3.10/site-packages/scikeras/wrappers.py\", line 760, in fit\n    self._fit(\n  File \"/Users/wtc/anaconda3/envs/tf-metal/lib/python3.10/site-packages/scikeras/wrappers.py\", line 928, in _fit\n    self._fit_keras_model(\n  File \"/Users/wtc/anaconda3/envs/tf-metal/lib/python3.10/site-packages/scikeras/wrappers.py\", line 524, in _fit_keras_model\n    hist = self.model_.fit(x=X, y=y, **fit_args)\n  File \"/Users/wtc/anaconda3/envs/tf-metal/lib/python3.10/site-packages/keras/src/utils/traceback_utils.py\", line 70, in error_handler\n    raise e.with_traceback(filtered_tb) from None\n  File \"/var/folders/4w/p3jk6v8j135cv56t4gzkzv3r0000gn/T/__autograph_generated_fileskpy5br1.py\", line 15, in tf__train_function\n    retval_ = ag__.converted_call(ag__.ld(step_function), (ag__.ld(self), ag__.ld(iterator)), None, fscope)\nValueError: in user code:\n\n    File \"/Users/wtc/anaconda3/envs/tf-metal/lib/python3.10/site-packages/keras/src/engine/training.py\", line 1338, in train_function  *\n        return step_function(self, iterator)\n    File \"/Users/wtc/anaconda3/envs/tf-metal/lib/python3.10/site-packages/keras/src/engine/training.py\", line 1322, in step_function  **\n        outputs = model.distribute_strategy.run(run_step, args=(data,))\n    File \"/Users/wtc/anaconda3/envs/tf-metal/lib/python3.10/site-packages/keras/src/engine/training.py\", line 1303, in run_step  **\n        outputs = model.train_step(data)\n    File \"/Users/wtc/anaconda3/envs/tf-metal/lib/python3.10/site-packages/keras/src/engine/training.py\", line 1081, in train_step\n        loss = self.compute_loss(x, y, y_pred, sample_weight)\n    File \"/Users/wtc/anaconda3/envs/tf-metal/lib/python3.10/site-packages/keras/src/engine/training.py\", line 1139, in compute_loss\n        return self.compiled_loss(\n    File \"/Users/wtc/anaconda3/envs/tf-metal/lib/python3.10/site-packages/keras/src/engine/compile_utils.py\", line 265, in __call__\n        loss_value = loss_obj(y_t, y_p, sample_weight=sw)\n    File \"/Users/wtc/anaconda3/envs/tf-metal/lib/python3.10/site-packages/keras/src/losses.py\", line 142, in __call__\n        losses = call_fn(y_true, y_pred)\n    File \"/Users/wtc/anaconda3/envs/tf-metal/lib/python3.10/site-packages/keras/src/losses.py\", line 268, in call  **\n        return ag_fn(y_true, y_pred, **self._fn_kwargs)\n    File \"/Users/wtc/anaconda3/envs/tf-metal/lib/python3.10/site-packages/keras/src/losses.py\", line 2122, in categorical_crossentropy\n        return backend.categorical_crossentropy(\n    File \"/Users/wtc/anaconda3/envs/tf-metal/lib/python3.10/site-packages/keras/src/backend.py\", line 5560, in categorical_crossentropy\n        target.shape.assert_is_compatible_with(output.shape)\n\n    ValueError: Shapes (None, 8) and (None, 28, 28, 8) are incompatible\n\n\n--------------------------------------------------------------------------------\n1 fits failed with the following error:\nTraceback (most recent call last):\n  File \"/Users/wtc/anaconda3/envs/tf-metal/lib/python3.10/site-packages/sklearn/model_selection/_validation.py\", line 732, in _fit_and_score\n    estimator.fit(X_train, y_train, **fit_params)\n  File \"/Users/wtc/anaconda3/envs/tf-metal/lib/python3.10/site-packages/scikeras/wrappers.py\", line 1491, in fit\n    super().fit(X=X, y=y, sample_weight=sample_weight, **kwargs)\n  File \"/Users/wtc/anaconda3/envs/tf-metal/lib/python3.10/site-packages/scikeras/wrappers.py\", line 760, in fit\n    self._fit(\n  File \"/Users/wtc/anaconda3/envs/tf-metal/lib/python3.10/site-packages/scikeras/wrappers.py\", line 928, in _fit\n    self._fit_keras_model(\n  File \"/Users/wtc/anaconda3/envs/tf-metal/lib/python3.10/site-packages/scikeras/wrappers.py\", line 524, in _fit_keras_model\n    hist = self.model_.fit(x=X, y=y, **fit_args)\n  File \"/Users/wtc/anaconda3/envs/tf-metal/lib/python3.10/site-packages/keras/src/utils/traceback_utils.py\", line 70, in error_handler\n    raise e.with_traceback(filtered_tb) from None\n  File \"/var/folders/4w/p3jk6v8j135cv56t4gzkzv3r0000gn/T/__autograph_generated_filejxk2y29r.py\", line 15, in tf__train_function\n    retval_ = ag__.converted_call(ag__.ld(step_function), (ag__.ld(self), ag__.ld(iterator)), None, fscope)\nValueError: in user code:\n\n    File \"/Users/wtc/anaconda3/envs/tf-metal/lib/python3.10/site-packages/keras/src/engine/training.py\", line 1338, in train_function  *\n        return step_function(self, iterator)\n    File \"/Users/wtc/anaconda3/envs/tf-metal/lib/python3.10/site-packages/keras/src/engine/training.py\", line 1322, in step_function  **\n        outputs = model.distribute_strategy.run(run_step, args=(data,))\n    File \"/Users/wtc/anaconda3/envs/tf-metal/lib/python3.10/site-packages/keras/src/engine/training.py\", line 1303, in run_step  **\n        outputs = model.train_step(data)\n    File \"/Users/wtc/anaconda3/envs/tf-metal/lib/python3.10/site-packages/keras/src/engine/training.py\", line 1081, in train_step\n        loss = self.compute_loss(x, y, y_pred, sample_weight)\n    File \"/Users/wtc/anaconda3/envs/tf-metal/lib/python3.10/site-packages/keras/src/engine/training.py\", line 1139, in compute_loss\n        return self.compiled_loss(\n    File \"/Users/wtc/anaconda3/envs/tf-metal/lib/python3.10/site-packages/keras/src/engine/compile_utils.py\", line 265, in __call__\n        loss_value = loss_obj(y_t, y_p, sample_weight=sw)\n    File \"/Users/wtc/anaconda3/envs/tf-metal/lib/python3.10/site-packages/keras/src/losses.py\", line 142, in __call__\n        losses = call_fn(y_true, y_pred)\n    File \"/Users/wtc/anaconda3/envs/tf-metal/lib/python3.10/site-packages/keras/src/losses.py\", line 268, in call  **\n        return ag_fn(y_true, y_pred, **self._fn_kwargs)\n    File \"/Users/wtc/anaconda3/envs/tf-metal/lib/python3.10/site-packages/keras/src/losses.py\", line 2122, in categorical_crossentropy\n        return backend.categorical_crossentropy(\n    File \"/Users/wtc/anaconda3/envs/tf-metal/lib/python3.10/site-packages/keras/src/backend.py\", line 5560, in categorical_crossentropy\n        target.shape.assert_is_compatible_with(output.shape)\n\n    ValueError: Shapes (None, 8) and (None, 28, 28, 8) are incompatible\n\n"
     ]
    }
   ],
   "source": [
    "# Use scikit-learn to grid search the batch size and epochs\n",
    "import numpy as np\n",
    "import tensorflow as tf\n",
    "from sklearn.model_selection import GridSearchCV\n",
    "from tensorflow.keras.models import Sequential\n",
    "from tensorflow.keras.layers import Dense\n",
    "from scikeras.wrappers import KerasClassifier\n",
    "# Function to create model, required for KerasClassifier\n",
    "def create_model():\n",
    "\t# create model\n",
    "\tmodel = Sequential()\n",
    "\tmodel.add(Dense(12, input_shape=[28,28,3], activation='relu'))\n",
    "\tmodel.add(Dense(8, activation='softmax'))\n",
    "\t# Compile model\n",
    "\tmodel.compile(loss='categorical_crossentropy', optimizer='adam', metrics=['categorical_accuracy'])\n",
    "\treturn model\n",
    "\n",
    "# create model\n",
    "model = KerasClassifier(model=create_model, verbose=0)\n",
    "# define the grid search parameters\n",
    "batch_size = [10, 20]\n",
    "epochs = [10, 20]\n",
    "param_grid = dict(batch_size=batch_size, epochs=epochs)\n",
    "grid = GridSearchCV(estimator=model, param_grid=param_grid, n_jobs=-1, cv=3)\n",
    "grid_result = grid.fit(X_train_n, y_train_c)\n",
    "# summarize results\n",
    "print(\"Best: %f using %s\" % (grid_result.best_score_, grid_result.best_params_))\n",
    "means = grid_result.cv_results_['mean_test_score']\n",
    "stds = grid_result.cv_results_['std_test_score']\n",
    "params = grid_result.cv_results_['params']\n",
    "for mean, stdev, param in zip(means, stds, params):\n",
    "    print(\"%f (%f) with: %r\" % (mean, stdev, param))"
   ]
  }
 ],
 "metadata": {
  "kernelspec": {
   "display_name": "tf-metal",
   "language": "python",
   "name": "python3"
  },
  "language_info": {
   "codemirror_mode": {
    "name": "ipython",
    "version": 3
   },
   "file_extension": ".py",
   "mimetype": "text/x-python",
   "name": "python",
   "nbconvert_exporter": "python",
   "pygments_lexer": "ipython3",
   "version": "3.10.13"
  },
  "orig_nbformat": 4
 },
 "nbformat": 4,
 "nbformat_minor": 2
}
